Workbook

Sheet Datos Originales
A1: Fecha de venta | B1: Ciudad | C1: Producto | D1: Precio unitario | E1: Cantidad | F1: Monto total | G1: Cliente | H1: Email | I1: ID de orden
A2: Oct 03, 2024 | B2: Monterrey | C2: Auriculares-Con cable-32GB | D2: 439.01 | E2: 5 | F2: 2195.05 | G2: Sandra B√°ez | H2: maria-teresamanzanares@jaquez.com | I2: d7c9e19e-1228-4326-8b2a-cde42e222a67
A3: 10/15/2024 | B3: Bogotá | C3: Auriculares-Bluetooth-8GB | D3: 1090.69 | E3: 1 | F3: 1090.69 | G3: Mariano Leticia Palomino | H3: brunoflorez@hotmail.com | I3: c1103728-e36d-48da-ba95-42c7fc1ccca5
A4: 27/10/2024 | B4: Bogotá | C4: Laptop-Gaming-32GB | D4: 1174.54 | E4: 2 | F4: 2349.08 | G4: Gregorio Gayt√°n | H4: maytezedillo@grupo.com | I4: 1fd52e4f-ce34-4747-8dc7-fa4b9fe57dc4
A5: Nov 02, 2024 | B5: Medellín | C5: Tablet-Pro-8GB | D5: 1291.38 | E5: 4 | F5: 5165.52 | G5: Alejandra Araceli Guti√©rrez | H5: jtovar@trujillo-orellana.com | I5: 0ada26be-f753-405b-a1a4-3599df81e700
A6: 28/11/2024 | B6: Medellín | C6: Teléfono-Gama alta-4GB | D6: 1450.89 | E6: 1 | F6: 1450.89 | G6: Miguel √Ångel Mondrag√≥n Benav√≠dez | H6: bmontanez@yahoo.com | I6: 9300cdf6-1250-4659-917a-93641a266da5
A7: 11/05/2024 | B7: Cali | C7: Teléfono-Gama alta-8GB | D7: 670.67 | E7: 4 | F7: 2682.68 | G7: Gabino Conchita Bueno | H7: wvega@yahoo.com | I7: c46fe29a-c3e5-4c00-b9ea-94b719c84734
A8: Dec 01, 2024 | B8: Guadalajara | C8: Tablet-Mini-4GB | D8: 1114.1 | E8: 3 | F8: 3342.3 | G8: Karla Pineda Arriaga | H8: acabrera@yahoo.com | I8: 35bff7d1-834a-47b1-8627-e9ce0847bae9
A9: 12/10/2024 | B9: Ciudad de M√©xico | C9: Tablet-Pro-8GB | D9: 1001.63 | E9: 3 | F9: 3004.89 | G9: Dr. Rolando Mares | H9: mercadohilda@gmail.com | I9: 5199a25e-ee56-4e1f-9c71-21f24998e8fc
A10: 15/12/2024 | B10: Cali | C10: Laptop-Ultraliviana-16GB | D10: 181.56 | E10: 4 | F10: 726.24 | G10: Virginia Mondrag√≥n | H10: josefina68@proyectos.com | I10: e58774cc-8183-4c21-b23d-1089685c61dd
A11: 23/12/2024 | B11: GUADALAJARA | C11: Tablet-Mini-4GB | D11: 964.35 | E11: 5 | F11: 4821.75 | G11: Luis Manuel Aldonza Contreras | H11: castilloteodoro@yahoo.com | I11: 4e85609f-8a23-4d99-a616-2f83279d0dc0
A12: Oct 09, 2024 | B12: Bogotá | C12: Auriculares-Bluetooth-16GB | D12: 120.46 | E12: 1 | F12: 120.46 | G12: Indira Guadalupe Montez Alcaraz | H12: brivera@club.com | I12: a076e80e-95f4-4b8d-8e0e-af032fd3e7e3
A13: 11/25/2024 | B13: Medellín | C13: Auriculares-Con cable-16GB | D13: 1061.61 | E13: 1 | F13: 1061.61 | G13: Lic. Luz de la Garza | H13: esparta94@gmail.com | I13: b76b9aa0-31e3-4e6d-905f-d7fc227d629a
... A15: 10/21/2024 | B15: Monterrey | C15: Teléfono-Gama baja-16GB | D15: 121.68 | E15: 2 | F15: 243.36 | G15: Abril Julio T√≥rrez Segovia | H15: xsaenz@hotmail.com | I15: 0281b754-3298-47cb-85b3-b7e7a8c57bab
A16: Nov 30, 2024 | B16: Guadalajara | C16: Tablet-Pro-32GB | D16: 1109.64 | E16: 3 | G16: Ing. Esteban Curiel | H16: juliavergara@barraza.info | I16: 6d6dc8da-1c46-48a9-9864-d6731b144bc7
A17: 12/05/2024 | B17: Guadalajara | C17: Tablet-Mini-32GB | D17: 2246.48 | E17: 1 | F17: 2246.48 | G17: Hilda M√≥nica Acu√±a Zedillo | H17: lhidalgo@yahoo.com | I17: 6d865eac-7ee1-4c9f-bf09-98a0163a585b
A18: 22/10/2024 | B18: Bogotá | C18: Auriculares-Cancelación de ruido-4GB | D18: 129.07 | E18: 4 | F18: 516.28 | G18: Iv√°n Sanches Vallejo | H18: reinaenriquez@sarabia-badillo.com | I18: 166ba421-1a83-493d-b4f5-5832605721e4
A19: Dec 28, 2024 | B19: Monterrey | C19: Auriculares-Bluetooth-16GB | D19: 1724.31 | E19: 2 | F19: 3448.62 | G19: Alejandra Rold√°n | H19: almafajardo@proyectos.com | I19: 530801f5-4c88-4d00-b297-5944ebece83d
A20: 10/12/2024 | B20: Bogotá | C20: Teléfono-Gama alta-16GB | D20: 1445.1 | E20: 4 | F20: 5780.4 | G20: Lorenzo Wendolin M√©ndez Gollum | H20: ffuentes@ochoa-molina.com | I20: 116022d7-56fc-4596-aeba-30c58ab21dbf
A21: Nov 14, 2024 | B21: Cali | C21: Tablet-Estándar-16GB | D21: 1618.43 | E21: 3 | F21: 4855.29 | G21: Catalina Adela Galarza Camacho | H21: yfarias@industrias.com | I21: 6685e5bb-9081-494c-b6aa-422ddb87955d
A22: 29/12/2024 | B22: Ciudad de M√©xico | C22: Teléfono-Gama media-4GB | D22: 2070.23 | E22: 5 | F22: 10351.15 | G22: Aldo Rodr√≠gez | H22: isabelojeda@grupo.com | I22: f8087330-1de4-4af6-8cae-e91d660b819f
A23: 11/10/2024 | B23: Medellín | C23: Teléfono-Gama baja-8GB | D23: 763.62 | E23: 1 | F23: 763.62 | G23: Sr(a). Carlota Aguayo | H23: auroralugo@acuna-mercado.com | I23: d58eb71d-bd78-4ec3-8a70-34213c01464b
A24: Dec 16, 2024 | B24: Monterrey | C24: Teléfono-Gama media-4GB | D24: 658.01 | E24: 5 | F24: 3290.05 | G24: Aurora Amador Mendoza Prieto | H24: margarita69@grupo.net | I24: 45698812-aa8b-4fea-b214-81743c8c3e1d
A25: 14/10/2024 | B25: MONTERREY | C25: Tablet-Pro-4GB | D25: 162.56 | E25: 4 | F25: 650.24 | G25: Gabino Rub√©n Men√©ndez | H25: bernardovillagomez@laboratorios.org | I25: df7f87e2-753a-411f-bbe9-b634b149f17c
A26: 12/31/2024 | B26: Cali | C26: Laptop-Ultraliviana-32GB | D26: 1721.22 | E26: 4 | F26: 6884.88 | G26: Roberto Mar√≠a Cristina Madera Alejandro | H26: teodoro56@yahoo.com | I26: bfde20ee-a837-4bd7-af36-f9e5b40dfe3b
A27: Oct 03, 2024 | B27: Bogotá | C27: Tablet-Estándar-16GB | D27: 741.79 | E27: 2 | F27: 1483.58 | G27: Uriel Helena Caldera | H27: pizarrojaqueline@acuna-moreno.com | I27: 91de2837-a873-4607-8185-7fa6844d2be8
A28: 11/10/2024 | B28: CIUDAD DE M√âXICO | C28: Auriculares-Cancelación de ruido-4GB | D28: 489.42 | E28: 3 | F28: 1468.26 | G28: Sr(a). M√≥nica Cortez | H28: benito43@corporacin.com | I28: 814e531c-1781-4af9-86e2-0da4494565c9
... A57: 12/18/2024 | B57: Bogotá | C57: Laptop-Ultraliviana-16GB | D57: 602.68 | E57: 3 | F57: 1808.04 | G57: Lic. Ricardo Coronado | H57: opaz@proyectos.net | I57: 84862dcd-d58c-423c-99b1-8b1ee8b38e4e
A58: 11/17/2024 | B58: Medellín | C58: Teléfono-Gama alta-32GB | D58: 2405.31 | E58: 5 | G58: Virginia Aldonza Zamora Longoria | H58: bpacheco@hotmail.com | I58: 512f8818-bb8d-466a-9f10-79bd8f52408b
A59: Nov 25, 2024 | B59: Guadalajara | C59: Auriculares-Bluetooth-16GB | D59: 564.69 | E59: 2 | F59: 1129.38 | G59: Alonso Paola Rocha | H59: ujasso@olivares.com | I59: 8588db90-3e5f-471e-8500-c89cbc6d1623
A60: 12/20/2024 | B60: Cali | C60: Teléfono-Gama media-4GB | D60: 2373.12 | E60: 2 | F60: 4746.24 | G60: Aida Marrero | H60: juana18@yahoo.com | I60: 84603ef1-6930-4a3e-b3f4-2e56b1a84398
A61: 10/10/2024 | B61: BOGOT√Å | C61: Laptop-Oficina-16GB | D61: 278.37 | E61: 3 | F61: 835.11 | G61: Mtro. C√©sar Verduzco | H61: maria-elena87@proyectos.biz | I61: af1640cb-8d21-4be4-a497-cf19ebe3fa3e
A62: Dec 07, 2024 | B62: Monterrey | C62: Laptop-Gaming-4GB | D62: 1636.89 | E62: 2 | F62: 3273.78 | G62: Rodrigo Yeni Avil√©s | H62: juan-carlos48@del.info | I62: fa21bde8-c128-4e66-83c3-a35891b527e7
A63: 11/13/2024 | B63: Bogotá | C63: Auriculares-Bluetooth-4GB | E63: 1 | F63: 1787.41 | G63: Cynthia Aguilera Figueroa | H63: eloyarroyo@yahoo.com | I63: 6a533065-10e9-417f-90b8-cc321916284c
A64: 12/02/2024 | B64: GUADALAJARA | C64: Tablet-Mini-16GB | D64: 218.94 | E64: 3 | F64: 656.82 | G64: Omar Casares Benav√≠dez | H64: humberto17@tapia.com | I64: be2593fe-882a-47b4-84fb-96d56973714b
A65: Nov 19, 2024 | B65: Monterrey | C65: Laptop-Ultraliviana-4GB | D65: 1077.1 | E65: 5 | F65: 5385.5 | G65: Sr(a). Mario Cort√©s | H65: oliviacarmona@magana.net | I65: 9b5f5828-58aa-4107-b467-e223f64cae41
A66: 21/11/2024 | B66: Ciudad de M√©xico | C66: Laptop-Oficina-4GB | D66: 2297.78 | E66: 4 | F66: 9191.12 | G66: Delia Rosario | H66: guruleserafin@industrias.biz | I66: a23fb156-d7f0-48b3-8429-51722fc91010
A67: 11/07/2024 | B67: Ciudad de M√©xico | C67: Tablet-Estándar-4GB | D67: 127.95 | E67: 4 | F67: 511.8 | G67: Citlali Jorge Gast√©lum | H67: patricia75@corporacin.com | I67: b7d845eb-4a64-4099-a793-3f93363ea49e
A68: Dec 31, 2024 | B68: Cali | C68: Teléfono-Gama alta-4GB | D68: 1545.28 | E68: 2 | F68: 3090.56 | G68: Lic. Mateo Salazar | H68: aurora38@hotmail.com | I68: 8d472941-b5df-4f80-b3a6-ece0e6978e8a
A69: 24/12/2024 | B69: Medellín | C69: Tablet-Estándar-16GB | D69: 97.52 | E69: 1 | F69: 97.52 | G69: Ing. Emilia Fajardo | H69: estelarocha@oquendo.org | I69: 8e37e816-5b3d-4cf1-9cef-cf002ceb456f
...

Sheet Datos_Limpios
A1: Fecha de venta | B1: Ciudad | C1: Producto | D1: Precio unitario | E1: Cantidad | F1: Monto total | G1: Cliente | H1: Email | I1: ID de orden | K1: Columna 1 | L1: Fecha | M1: Ciudad | N1: Producto | O1: Tipo | P1: Especificaciones | Q1: Precio unitario | R1: Cantidad | S1: Monto total | T1: Cliente | U1: ID de orden | V1: Producto unido
A2: 45568 | B2: Monterrey | C2: Auriculares-Con cable-32GB | D2: 439.01 | E2: 5 | F2: 2195.05 | G2: Sandra B√°ez | H2: maria-teresamanzanares@jaquez.com | I2: d7c9e19e-1228-4326-8b2a-cde42e222a67 | K2: =IFERROR(__xludf.DUMMYFUNCTION("IF(ISBLANK(A2), """", IF(ISNUMBER(A2), TEXT(A2,""dd/mm/yyyy""), IF( REGEXMATCH(TRIM(A2),""^\d{1,2}/\d{1,2}/\d{4}$""), TRIM(A2), IFERROR( TEXT(DATEVALUE(SUBSTITUTE(SUBSTITUTE(TRIM(A2),""-"",""/""),""."",""/"")),""dd/mm"&"/yyyy""), TRIM(A2) ) ) ) ) "),"03/10/2024") -> 03/10/2024 | L2: 45568 | M2: =IFERROR(__xludf.DUMMYFUNCTION("PROPER(TRIM( REGEXREPLACE( REGEXREPLACE( SUBSTITUTE(SUBSTITUTE(SUBSTITUTE(SUBSTITUTE(SUBSTITUTE(SUBSTITUTE(SUBSTITUTE(SUBSTITUTE(SUBSTITUTE(SUBSTITUTE(SUBSTITUTE( B2,""√©"",""é""),""√°"",""á""),""√±"",""ñ""),""√≥"",""ó""),""√â"",""é"")"&",""√Å"",""á""),""√ç"",""í""),""√Ç"",""Í""),""√Â"",""é""),""√≠"",""í""),""√º"",""ú""), ""[,\\.√]"",""""), ""\\s+"","" "") )) "),"Monterrey") -> Monterrey | N2: =IFERROR(__xludf.DUMMYFUNCTION("SPLIT( TRIM( SUBSTITUTE( SUBSTITUTE( SUBSTITUTE( SUBSTITUTE( C2, ""√©"", ""é"" ), ""√±"", ""ñ"" ), ""√°"", ""á"" ), ""√≥"", ""ó"" ) ), ""-"" ) "),"Auriculares") -> Auriculares | O2: =IFERROR(__xludf.DUMMYFUNCTION("""COMPUTED_VALUE"""),"Con cable") -> Con cable | P2: =IFERROR(__xludf.DUMMYFUNCTION("""COMPUTED_VALUE"""),"32GB") -> 32GB | Q2: =IF(ISBLANK(D2),"0",D2) -> 439.01 | R2: =IF(ISBLANK(E2),"Sin datos",E2) -> 5 | S2: =IF(ISBLANK(F2),"0",F2) -> 2195.05 | T2: =IFERROR(__xludf.DUMMYFUNCTION("PROPER(TRIM( LET( texto1, REGEXREPLACE(G2, ""(?i)\b(DR\.?|SRA?\.?|\(A\)|MTRO\.?|LIC\.?|ING\.?)\b"", """"), texto2, REGEXREPLACE(texto1, ""√©|√â|√Â"", ""é""), texto3, REGEXREPLACE(texto2, ""√°|√Å"", ""á""), texto4, REGEXREPLACE(texto3, """&"√±"", ""ñ""), texto5, REGEXREPLACE(texto4, ""√≥"", ""ó""), texto6, REGEXREPLACE(texto5, ""√ç|√≠|√Ç"", ""í""), texto7, REGEXREPLACE(texto6, ""√º"", ""ú""), texto8, REGEXREPLACE(texto7, ""[^A-Za-zÁÉÍÓÚÜÑáéíóúüñ\s]"", """"), texto9, REGEX"&"REPLACE(texto8, ""^[A-Za-zÁÉÍÓÚÜÑáéíóúüñ]\s+"", """"), texto10, IF(REGEXMATCH(texto9, ""(?i)^\s*Jos\s*$""), ""José"", texto9), texto11, REGEXREPLACE(texto10, ""(?i)(eé|ée|ee|éé)+"", ""é""), texto12, REGEXREPLACE(texto11, ""(?i)(aá|áa|aa|áá)+"""&", ""á""), texto13, REGEXREPLACE(texto12, ""(?i)(ií|íi|ii|íí)+"", ""í""), texto14, REGEXREPLACE(texto13, ""(?i)(oó|óo|oo|óó)+"", ""ó""), texto15, REGEXREPLACE(texto14, ""(?i)(uú|úu|uu|úú)+"", ""ú""), texto16, REGEXREPLACE(texto15, ""\s{2,}"&""", "" ""), texto16 ) )) "),"Sandra Báez") -> Sandra Báez | U2: =I2 -> d7c9e19e-1228-4326-8b2a-cde42e222a67 | V2: =CONCATENATE(N2," ",O2," ",P2) -> Auriculares Con cable 32GB
A3: 45580 | B3: Bogotá | C3: Auriculares-Bluetooth-8GB | D3: 1090.69 | E3: 1 | F3: 1090.69 | G3: Mariano Leticia Palomino | H3: brunoflorez@hotmail.com | I3: c1103728-e36d-48da-ba95-42c7fc1ccca5 | K3: =IFERROR(__xludf.DUMMYFUNCTION("IF(ISBLANK(A3), """", IF(ISNUMBER(A3), TEXT(A3,""dd/mm/yyyy""), IF( REGEXMATCH(TRIM(A3),""^\d{1,2}/\d{1,2}/\d{4}$""), TRIM(A3), IFERROR( TEXT(DATEVALUE(SUBSTITUTE(SUBSTITUTE(TRIM(A3),""-"",""/""),""."",""/"")),""dd/mm"&"/yyyy""), TRIM(A3) ) ) ) ) "),"15/10/2024") -> 15/10/2024 | L3: 45580 | M3: =IFERROR(__xludf.DUMMYFUNCTION("PROPER(TRIM( REGEXREPLACE( REGEXREPLACE( SUBSTITUTE(SUBSTITUTE(SUBSTITUTE(SUBSTITUTE(SUBSTITUTE(SUBSTITUTE(SUBSTITUTE(SUBSTITUTE(SUBSTITUTE(SUBSTITUTE(SUBSTITUTE( B3,""√©"",""é""),""√°"",""á""),""√±"",""ñ""),""√≥"",""ó""),""√â"",""é"")"&",""√Å"",""á""),""√ç"",""í""),""√Ç"",""Í""),""√Â"",""é""),""√≠"",""í""),""√º"",""ú""), ""[,\\.√]"",""""), ""\\s+"","" "") )) "),"Bogotá") -> Bogotá | N3: =IFERROR(__xludf.DUMMYFUNCTION("SPLIT( TRIM( SUBSTITUTE( SUBSTITUTE( SUBSTITUTE( SUBSTITUTE( C3, ""√©"", ""é"" ), ""√±"", ""ñ"" ), ""√°"", ""á"" ), ""√≥"", ""ó"" ) ), ""-"" ) "),"Auriculares") -> Auriculares | O3: =IFERROR(__xludf.DUMMYFUNCTION("""COMPUTED_VALUE"""),"Bluetooth") -> Bluetooth | P3: =IFERROR(__xludf.DUMMYFUNCTION("""COMPUTED_VALUE"""),"8GB") -> 8GB | Q3: =IF(ISBLANK(D3),"0",D3) -> 1090.69 | R3: =IF(ISBLANK(E3),"Sin datos",E3) -> 1 | S3: =IF(ISBLANK(F3),"0",F3) -> 1090.69 | T3: =IFERROR(__xludf.DUMMYFUNCTION("PROPER(TRIM( LET( texto1, REGEXREPLACE(G3, ""(?i)\b(DR\.?|SRA?\.?|\(A\)|MTRO\.?|LIC\.?|ING\.?)\b"", """"), texto2, REGEXREPLACE(texto1, ""√©|√â|√Â"", ""é""), texto3, REGEXREPLACE(texto2, ""√°|√Å"", ""á""), texto4, REGEXREPLACE(texto3, """&"√±"", ""ñ""), texto5, REGEXREPLACE(texto4, ""√≥"", ""ó""), texto6, REGEXREPLACE(texto5, ""√ç|√≠|√Ç"", ""í""), texto7, REGEXREPLACE(texto6, ""√º"", ""ú""), texto8, REGEXREPLACE(texto7, ""[^A-Za-zÁÉÍÓÚÜÑáéíóúüñ\s]"", """"), texto9, REGEX"&"REPLACE(texto8, ""^[A-Za-zÁÉÍÓÚÜÑáéíóúüñ]\s+"", """"), texto10, IF(REGEXMATCH(texto9, ""(?i)^\s*Jos\s*$""), ""José"", texto9), texto11, REGEXREPLACE(texto10, ""(?i)(eé|ée|ee|éé)+"", ""é""), texto12, REGEXREPLACE(texto11, ""(?i)(aá|áa|aa|áá)+"""&", ""á""), texto13, REGEXREPLACE(texto12, ""(?i)(ií|íi|ii|íí)+"", ""í""), texto14, REGEXREPLACE(texto13, ""(?i)(oó|óo|oo|óó)+"", ""ó""), texto15, REGEXREPLACE(texto14, ""(?i)(uú|úu|uu|úú)+"", ""ú""), texto16, REGEXREPLACE(texto15, ""\s{2,}"&""", "" ""), texto16 ) )) "),"Mariano Leticia Palomino") -> Mariano Leticia Palomino | U3: =I3 -> c1103728-e36d-48da-ba95-42c7fc1ccca5 | V3: =CONCATENATE(N3," ",O3," ",P3) -> Auriculares Bluetooth 8GB
A4: 27/10/2024 | B4: Bogotá | C4: Laptop-Gaming-32GB | D4: 1174.54 | E4: 2 | F4: 2349.08 | G4: Gregorio Gayt√°n | H4: maytezedillo@grupo.com | I4: 1fd52e4f-ce34-4747-8dc7-fa4b9fe57dc4 | K4: =IFERROR(__xludf.DUMMYFUNCTION("IF(ISBLANK(A4), """", IF(ISNUMBER(A4), TEXT(A4,""dd/mm/yyyy""), IF( REGEXMATCH(TRIM(A4),""^\d{1,2}/\d{1,2}/\d{4}$""), TRIM(A4), IFERROR( TEXT(DATEVALUE(SUBSTITUTE(SUBSTITUTE(TRIM(A4),""-"",""/""),""."",""/"")),""dd/mm"&"/yyyy""), TRIM(A4) ) ) ) ) "),"27/10/2024") -> 27/10/2024 | L4: 45592 | M4: =IFERROR(__xludf.DUMMYFUNCTION("PROPER(TRIM( REGEXREPLACE( REGEXREPLACE( SUBSTITUTE(SUBSTITUTE(SUBSTITUTE(SUBSTITUTE(SUBSTITUTE(SUBSTITUTE(SUBSTITUTE(SUBSTITUTE(SUBSTITUTE(SUBSTITUTE(SUBSTITUTE( B4,""√©"",""é""),""√°"",""á""),""√±"",""ñ""),""√≥"",""ó""),""√â"",""é"")"&",""√Å"",""á""),""√ç"",""í""),""√Ç"",""Í""),""√Â"",""é""),""√≠"",""í""),""√º"",""ú""), ""[,\\.√]"",""""), ""\\s+"","" "") )) "),"Bogotá") -> Bogotá | N4: =IFERROR(__xludf.DUMMYFUNCTION("SPLIT( TRIM( SUBSTITUTE( SUBSTITUTE( SUBSTITUTE( SUBSTITUTE( C4, ""√©"", ""é"" ), ""√±"", ""ñ"" ), ""√°"", ""á"" ), ""√≥"", ""ó"" ) ), ""-"" ) "),"Laptop") -> Laptop | O4: =IFERROR(__xludf.DUMMYFUNCTION("""COMPUTED_VALUE"""),"Gaming") -> Gaming | P4: =IFERROR(__xludf.DUMMYFUNCTION("""COMPUTED_VALUE"""),"32GB") -> 32GB | Q4: =IF(ISBLANK(D4),"0",D4) -> 1174.54 | R4: =IF(ISBLANK(E4),"Sin datos",E4) -> 2 | S4: =IF(ISBLANK(F4),"0",F4) -> 2349.08 | T4: =IFERROR(__xludf.DUMMYFUNCTION("PROPER(TRIM( LET( texto1, REGEXREPLACE(G4, ""(?i)\b(DR\.?|SRA?\.?|\(A\)|MTRO\.?|LIC\.?|ING\.?)\b"", """"), texto2, REGEXREPLACE(texto1, ""√©|√â|√Â"", ""é""), texto3, REGEXREPLACE(texto2, ""√°|√Å"", ""á""), texto4, REGEXREPLACE(texto3, """&"√±"", ""ñ""), texto5, REGEXREPLACE(texto4, ""√≥"", ""ó""), texto6, REGEXREPLACE(texto5, ""√ç|√≠|√Ç"", ""í""), texto7, REGEXREPLACE(texto6, ""√º"", ""ú""), texto8, REGEXREPLACE(texto7, ""[^A-Za-zÁÉÍÓÚÜÑáéíóúüñ\s]"", """"), texto9, REGEX"&"REPLACE(texto8, ""^[A-Za-zÁÉÍÓÚÜÑáéíóúüñ]\s+"", """"), texto10, IF(REGEXMATCH(texto9, ""(?i)^\s*Jos\s*$""), ""José"", texto9), texto11, REGEXREPLACE(texto10, ""(?i)(eé|ée|ee|éé)+"", ""é""), texto12, REGEXREPLACE(texto11, ""(?i)(aá|áa|aa|áá)+"""&", ""á""), texto13, REGEXREPLACE(texto12, ""(?i)(ií|íi|ii|íí)+"", ""í""), texto14, REGEXREPLACE(texto13, ""(?i)(oó|óo|oo|óó)+"", ""ó""), texto15, REGEXREPLACE(texto14, ""(?i)(uú|úu|uu|úú)+"", ""ú""), texto16, REGEXREPLACE(texto15, ""\s{2,}"&""", "" ""), texto16 ) )) "),"Gregorio Gaytán") -> Gregorio Gaytán | U4: =I4 -> 1fd52e4f-ce34-4747-8dc7-fa4b9fe57dc4 | V4: =CONCATENATE(N4," ",O4," ",P4) -> Laptop Gaming 32GB
A5: 45598 | B5: Medellín | C5: Tablet-Pro-8GB | D5: 1291.38 | E5: 4 | F5: 5165.52 | G5: Alejandra Araceli Guti√©rrez | H5: jtovar@trujillo-orellana.com | I5: 0ada26be-f753-405b-a1a4-3599df81e700 | K5: =IFERROR(__xludf.DUMMYFUNCTION("IF(ISBLANK(A5), """", IF(ISNUMBER(A5), TEXT(A5,""dd/mm/yyyy""), IF( REGEXMATCH(TRIM(A5),""^\d{1,2}/\d{1,2}/\d{4}$""), TRIM(A5), IFERROR( TEXT(DATEVALUE(SUBSTITUTE(SUBSTITUTE(TRIM(A5),""-"",""/""),""."",""/"")),""dd/mm"&"/yyyy""), TRIM(A5) ) ) ) ) "),"02/11/2024") -> 02/11/2024 | L5: 45598 | M5: =IFERROR(__xludf.DUMMYFUNCTION("PROPER(TRIM( REGEXREPLACE( REGEXREPLACE( SUBSTITUTE(SUBSTITUTE(SUBSTITUTE(SUBSTITUTE(SUBSTITUTE(SUBSTITUTE(SUBSTITUTE(SUBSTITUTE(SUBSTITUTE(SUBSTITUTE(SUBSTITUTE( B5,""√©"",""é""),""√°"",""á""),""√±"",""ñ""),""√≥"",""ó""),""√â"",""é"")"&",""√Å"",""á""),""√ç"",""í""),""√Ç"",""Í""),""√Â"",""é""),""√≠"",""í""),""√º"",""ú""), ""[,\\.√]"",""""), ""\\s+"","" "") )) "),"Medellín") -> Medellín | N5: =IFERROR(__xludf.DUMMYFUNCTION("SPLIT( TRIM( SUBSTITUTE( SUBSTITUTE( SUBSTITUTE( SUBSTITUTE( C5, ""√©"", ""é"" ), ""√±"", ""ñ"" ), ""√°"", ""á"" ), ""√≥"", ""ó"" ) ), ""-"" ) "),"Tablet") -> Tablet | O5: =IFERROR(__xludf.DUMMYFUNCTION("""COMPUTED_VALUE"""),"Pro") -> Pro | P5: =IFERROR(__xludf.DUMMYFUNCTION("""COMPUTED_VALUE"""),"8GB") -> 8GB | Q5: =IF(ISBLANK(D5),"0",D5) -> 1291.38 | R5: =IF(ISBLANK(E5),"Sin datos",E5) -> 4 | S5: =IF(ISBLANK(F5),"0",F5) -> 5165.52 | T5: =IFERROR(__xludf.DUMMYFUNCTION("PROPER(TRIM( LET( texto1, REGEXREPLACE(G5, ""(?i)\b(DR\.?|SRA?\.?|\(A\)|MTRO\.?|LIC\.?|ING\.?)\b"", """"), texto2, REGEXREPLACE(texto1, ""√©|√â|√Â"", ""é""), texto3, REGEXREPLACE(texto2, ""√°|√Å"", ""á""), texto4, REGEXREPLACE(texto3, """&"√±"", ""ñ""), texto5, REGEXREPLACE(texto4, ""√≥"", ""ó""), texto6, REGEXREPLACE(texto5, ""√ç|√≠|√Ç"", ""í""), texto7, REGEXREPLACE(texto6, ""√º"", ""ú""), texto8, REGEXREPLACE(texto7, ""[^A-Za-zÁÉÍÓÚÜÑáéíóúüñ\s]"", """"), texto9, REGEX"&"REPLACE(texto8, ""^[A-Za-zÁÉÍÓÚÜÑáéíóúüñ]\s+"", """"), texto10, IF(REGEXMATCH(texto9, ""(?i)^\s*Jos\s*$""), ""José"", texto9), texto11, REGEXREPLACE(texto10, ""(?i)(eé|ée|ee|éé)+"", ""é""), texto12, REGEXREPLACE(texto11, ""(?i)(aá|áa|aa|áá)+"""&", ""á""), texto13, REGEXREPLACE(texto12, ""(?i)(ií|íi|ii|íí)+"", ""í""), texto14, REGEXREPLACE(texto13, ""(?i)(oó|óo|oo|óó)+"", ""ó""), texto15, REGEXREPLACE(texto14, ""(?i)(uú|úu|uu|úú)+"", ""ú""), texto16, REGEXREPLACE(texto15, ""\s{2,}"&""", "" ""), texto16 ) )) "),"Alejandra Araceli Gutiérrez") -> Alejandra Araceli Gutiérrez | U5: =I5 -> 0ada26be-f753-405b-a1a4-3599df81e700 | V5: =CONCATENATE(N5," ",O5," ",P5) -> Tablet Pro 8GB
A6: 28/11/2024 | B6: Medellín | C6: Teléfono-Gama alta-4GB | D6: 1450.89 | E6: 1 | F6: 1450.89 | G6: Miguel √Ångel Mondrag√≥n Benav√≠dez | H6: bmontanez@yahoo.com | I6: 9300cdf6-1250-4659-917a-93641a266da5 | K6: =IFERROR(__xludf.DUMMYFUNCTION("IF(ISBLANK(A6), """", IF(ISNUMBER(A6), TEXT(A6,""dd/mm/yyyy""), IF( REGEXMATCH(TRIM(A6),""^\d{1,2}/\d{1,2}/\d{4}$""), TRIM(A6), IFERROR( TEXT(DATEVALUE(SUBSTITUTE(SUBSTITUTE(TRIM(A6),""-"",""/""),""."",""/"")),""dd/mm"&"/yyyy""), TRIM(A6) ) ) ) ) "),"28/11/2024") -> 28/11/2024 | L6: 45624 | M6: =IFERROR(__xludf.DUMMYFUNCTION("PROPER(TRIM( REGEXREPLACE( REGEXREPLACE( SUBSTITUTE(SUBSTITUTE(SUBSTITUTE(SUBSTITUTE(SUBSTITUTE(SUBSTITUTE(SUBSTITUTE(SUBSTITUTE(SUBSTITUTE(SUBSTITUTE(SUBSTITUTE( B6,""√©"",""é""),""√°"",""á""),""√±"",""ñ""),""√≥"",""ó""),""√â"",""é"")"&",""√Å"",""á""),""√ç"",""í""),""√Ç"",""Í""),""√Â"",""é""),""√≠"",""í""),""√º"",""ú""), ""[,\\.√]"",""""), ""\\s+"","" "") )) "),"Medellín") -> Medellín | N6: =IFERROR(__xludf.DUMMYFUNCTION("SPLIT( TRIM( SUBSTITUTE( SUBSTITUTE( SUBSTITUTE( SUBSTITUTE( C6, ""√©"", ""é"" ), ""√±"", ""ñ"" ), ""√°"", ""á"" ), ""√≥"", ""ó"" ) ), ""-"" ) "),"Teléfono") -> Teléfono | O6: =IFERROR(__xludf.DUMMYFUNCTION("""COMPUTED_VALUE"""),"Gama alta") -> Gama alta | P6: =IFERROR(__xludf.DUMMYFUNCTION("""COMPUTED_VALUE"""),"4GB") -> 4GB | Q6: =IF(ISBLANK(D6),"0",D6) -> 1450.89 | R6: =IF(ISBLANK(E6),"Sin datos",E6) -> 1 | S6: =IF(ISBLANK(F6),"0",F6) -> 1450.89 | T6: =IFERROR(__xludf.DUMMYFUNCTION("PROPER(TRIM( LET( texto1, REGEXREPLACE(G6, ""(?i)\b(DR\.?|SRA?\.?|\(A\)|MTRO\.?|LIC\.?|ING\.?)\b"", """"), texto2, REGEXREPLACE(texto1, ""√©|√â|√Â"", ""é""), texto3, REGEXREPLACE(texto2, ""√°|√Å"", ""á""), texto4, REGEXREPLACE(texto3, """&"√±"", ""ñ""), texto5, REGEXREPLACE(texto4, ""√≥"", ""ó""), texto6, REGEXREPLACE(texto5, ""√ç|√≠|√Ç"", ""í""), texto7, REGEXREPLACE(texto6, ""√º"", ""ú""), texto8, REGEXREPLACE(texto7, ""[^A-Za-zÁÉÍÓÚÜÑáéíóúüñ\s]"", """"), texto9, REGEX"&"REPLACE(texto8, ""^[A-Za-zÁÉÍÓÚÜÑáéíóúüñ]\s+"", """"), texto10, IF(REGEXMATCH(texto9, ""(?i)^\s*Jos\s*$""), ""José"", texto9), texto11, REGEXREPLACE(texto10, ""(?i)(eé|ée|ee|éé)+"", ""é""), texto12, REGEXREPLACE(texto11, ""(?i)(aá|áa|aa|áá)+"""&", ""á""), texto13, REGEXREPLACE(texto12, ""(?i)(ií|íi|ii|íí)+"", ""í""), texto14, REGEXREPLACE(texto13, ""(?i)(oó|óo|oo|óó)+"", ""ó""), texto15, REGEXREPLACE(texto14, ""(?i)(uú|úu|uu|úú)+"", ""ú""), texto16, REGEXREPLACE(texto15, ""\s{2,}"&""", "" ""), texto16 ) )) "),"Miguel Ángel Mondragón Benavídez") -> Miguel Ángel Mondragón Benavídez | U6: =I6 -> 9300cdf6-1250-4659-917a-93641a266da5 | V6: =CONCATENATE(N6," ",O6," ",P6) -> Teléfono Gama alta 4GB
A7: 45601 | B7: Cali | C7: Teléfono-Gama alta-8GB | D7: 670.67 | E7: 4 | F7: 2682.68 | G7: Gabino Conchita Bueno | H7: wvega@yahoo.com | I7: c46fe29a-c3e5-4c00-b9ea-94b719c84734 | K7: =IFERROR(__xludf.DUMMYFUNCTION("IF(ISBLANK(A7), """", IF(ISNUMBER(A7), TEXT(A7,""dd/mm/yyyy""), IF( REGEXMATCH(TRIM(A7),""^\d{1,2}/\d{1,2}/\d{4}$""), TRIM(A7), IFERROR( TEXT(DATEVALUE(SUBSTITUTE(SUBSTITUTE(TRIM(A7),""-"",""/""),""."",""/"")),""dd/mm"&"/yyyy""), TRIM(A7) ) ) ) ) "),"05/11/2024") -> 05/11/2024 | L7: 45601 | M7: =IFERROR(__xludf.DUMMYFUNCTION("PROPER(TRIM( REGEXREPLACE( REGEXREPLACE( SUBSTITUTE(SUBSTITUTE(SUBSTITUTE(SUBSTITUTE(SUBSTITUTE(SUBSTITUTE(SUBSTITUTE(SUBSTITUTE(SUBSTITUTE(SUBSTITUTE(SUBSTITUTE( B7,""√©"",""é""),""√°"",""á""),""√±"",""ñ""),""√≥"",""ó""),""√â"",""é"")"&",""√Å"",""á""),""√ç"",""í""),""√Ç"",""Í""),""√Â"",""é""),""√≠"",""í""),""√º"",""ú""), ""[,\\.√]"",""""), ""\\s+"","" "") )) "),"Cali") -> Cali | N7: =IFERROR(__xludf.DUMMYFUNCTION("SPLIT( TRIM( SUBSTITUTE( SUBSTITUTE( SUBSTITUTE( SUBSTITUTE( C7, ""√©"", ""é"" ), ""√±"", ""ñ"" ), ""√°"", ""á"" ), ""√≥"", ""ó"" ) ), ""-"" ) "),"Teléfono") -> Teléfono | O7: =IFERROR(__xludf.DUMMYFUNCTION("""COMPUTED_VALUE"""),"Gama alta") -> Gama alta | P7: =IFERROR(__xludf.DUMMYFUNCTION("""COMPUTED_VALUE"""),"8GB") -> 8GB | Q7: =IF(ISBLANK(D7),"0",D7) -> 670.67 | R7: =IF(ISBLANK(E7),"Sin datos",E7) -> 4 | S7: =IF(ISBLANK(F7),"0",F7) -> 2682.68 | T7: =IFERROR(__xludf.DUMMYFUNCTION("PROPER(TRIM( LET( texto1, REGEXREPLACE(G7, ""(?i)\b(DR\.?|SRA?\.?|\(A\)|MTRO\.?|LIC\.?|ING\.?)\b"", """"), texto2, REGEXREPLACE(texto1, ""√©|√â|√Â"", ""é""), texto3, REGEXREPLACE(texto2, ""√°|√Å"", ""á""), texto4, REGEXREPLACE(texto3, """&"√±"", ""ñ""), texto5, REGEXREPLACE(texto4, ""√≥"", ""ó""), texto6, REGEXREPLACE(texto5, ""√ç|√≠|√Ç"", ""í""), texto7, REGEXREPLACE(texto6, ""√º"", ""ú""), texto8, REGEXREPLACE(texto7, ""[^A-Za-zÁÉÍÓÚÜÑáéíóúüñ\s]"", """"), texto9, REGEX"&"REPLACE(texto8, ""^[A-Za-zÁÉÍÓÚÜÑáéíóúüñ]\s+"", """"), texto10, IF(REGEXMATCH(texto9, ""(?i)^\s*Jos\s*$""), ""José"", texto9), texto11, REGEXREPLACE(texto10, ""(?i)(eé|ée|ee|éé)+"", ""é""), texto12, REGEXREPLACE(texto11, ""(?i)(aá|áa|aa|áá)+"""&", ""á""), texto13, REGEXREPLACE(texto12, ""(?i)(ií|íi|ii|íí)+"", ""í""), texto14, REGEXREPLACE(texto13, ""(?i)(oó|óo|oo|óó)+"", ""ó""), texto15, REGEXREPLACE(texto14, ""(?i)(uú|úu|uu|úú)+"", ""ú""), texto16, REGEXREPLACE(texto15, ""\s{2,}"&""", "" ""), texto16 ) )) "),"Gabino Conchita Bueno") -> Gabino Conchita Bueno | U7: =I7 -> c46fe29a-c3e5-4c00-b9ea-94b719c84734 | V7: =CONCATENATE(N7," ",O7," ",P7) -> Teléfono Gama alta 8GB
A8: 45627 | B8: Guadalajara | C8: Tablet-Mini-4GB | D8: 1114.1 | E8: 3 | F8: 3342.3 | G8: Karla Pineda Arriaga | H8: acabrera@yahoo.com | I8: 35bff7d1-834a-47b1-8627-e9ce0847bae9 | K8: =IFERROR(__xludf.DUMMYFUNCTION("IF(ISBLANK(A8), """", IF(ISNUMBER(A8), TEXT(A8,""dd/mm/yyyy""), IF( REGEXMATCH(TRIM(A8),""^\d{1,2}/\d{1,2}/\d{4}$""), TRIM(A8), IFERROR( TEXT(DATEVALUE(SUBSTITUTE(SUBSTITUTE(TRIM(A8),""-"",""/""),""."",""/"")),""dd/mm"&"/yyyy""), TRIM(A8) ) ) ) ) "),"01/12/2024") -> 01/12/2024 | L8: 45627 | M8: =IFERROR(__xludf.DUMMYFUNCTION("PROPER(TRIM( REGEXREPLACE( REGEXREPLACE( SUBSTITUTE(SUBSTITUTE(SUBSTITUTE(SUBSTITUTE(SUBSTITUTE(SUBSTITUTE(SUBSTITUTE(SUBSTITUTE(SUBSTITUTE(SUBSTITUTE(SUBSTITUTE( B8,""√©"",""é""),""√°"",""á""),""√±"",""ñ""),""√≥"",""ó""),""√â"",""é"")"&",""√Å"",""á""),""√ç"",""í""),""√Ç"",""Í""),""√Â"",""é""),""√≠"",""í""),""√º"",""ú""), ""[,\\.√]"",""""), ""\\s+"","" "") )) "),"Guadalajara") -> Guadalajara | N8: =IFERROR(__xludf.DUMMYFUNCTION("SPLIT( TRIM( SUBSTITUTE( SUBSTITUTE( SUBSTITUTE( SUBSTITUTE( C8, ""√©"", ""é"" ), ""√±"", ""ñ"" ), ""√°"", ""á"" ), ""√≥"", ""ó"" ) ), ""-"" ) "),"Tablet") -> Tablet | O8: =IFERROR(__xludf.DUMMYFUNCTION("""COMPUTED_VALUE"""),"Mini") -> Mini | P8: =IFERROR(__xludf.DUMMYFUNCTION("""COMPUTED_VALUE"""),"4GB") -> 4GB | Q8: =IF(ISBLANK(D8),"0",D8) -> 1114.1 | R8: =IF(ISBLANK(E8),"Sin datos",E8) -> 3 | S8: =IF(ISBLANK(F8),"0",F8) -> 3342.3 | T8: =IFERROR(__xludf.DUMMYFUNCTION("PROPER(TRIM( LET( texto1, REGEXREPLACE(G8, ""(?i)\b(DR\.?|SRA?\.?|\(A\)|MTRO\.?|LIC\.?|ING\.?)\b"", """"), texto2, REGEXREPLACE(texto1, ""√©|√â|√Â"", ""é""), texto3, REGEXREPLACE(texto2, ""√°|√Å"", ""á""), texto4, REGEXREPLACE(texto3, """&"√±"", ""ñ""), texto5, REGEXREPLACE(texto4, ""√≥"", ""ó""), texto6, REGEXREPLACE(texto5, ""√ç|√≠|√Ç"", ""í""), texto7, REGEXREPLACE(texto6, ""√º"", ""ú""), texto8, REGEXREPLACE(texto7, ""[^A-Za-zÁÉÍÓÚÜÑáéíóúüñ\s]"", """"), texto9, REGEX"&"REPLACE(texto8, ""^[A-Za-zÁÉÍÓÚÜÑáéíóúüñ]\s+"", """"), texto10, IF(REGEXMATCH(texto9, ""(?i)^\s*Jos\s*$""), ""José"", texto9), texto11, REGEXREPLACE(texto10, ""(?i)(eé|ée|ee|éé)+"", ""é""), texto12, REGEXREPLACE(texto11, ""(?i)(aá|áa|aa|áá)+"""&", ""á""), texto13, REGEXREPLACE(texto12, ""(?i)(ií|íi|ii|íí)+"", ""í""), texto14, REGEXREPLACE(texto13, ""(?i)(oó|óo|oo|óó)+"", ""ó""), texto15, REGEXREPLACE(texto14, ""(?i)(uú|úu|uu|úú)+"", ""ú""), texto16, REGEXREPLACE(texto15, ""\s{2,}"&""", "" ""), texto16 ) )) "),"Karla Pineda Arriaga") -> Karla Pineda Arriaga | U8: =I8 -> 35bff7d1-834a-47b1-8627-e9ce0847bae9 | V8: =CONCATENATE(N8," ",O8," ",P8) -> Tablet Mini 4GB
A9: 45636 | B9: Ciudad de M√©xico | C9: Tablet-Pro-8GB | D9: 1001.63 | E9: 3 | F9: 3004.89 | G9: Dr. Rolando Mares | H9: mercadohilda@gmail.com | I9: 5199a25e-ee56-4e1f-9c71-21f24998e8fc | K9: =IFERROR(__xludf.DUMMYFUNCTION("IF(ISBLANK(A9), """", IF(ISNUMBER(A9), TEXT(A9,""dd/mm/yyyy""), IF( REGEXMATCH(TRIM(A9),""^\d{1,2}/\d{1,2}/\d{4}$""), TRIM(A9), IFERROR( TEXT(DATEVALUE(SUBSTITUTE(SUBSTITUTE(TRIM(A9),""-"",""/""),""."",""/"")),""dd/mm"&"/yyyy""), TRIM(A9) ) ) ) ) "),"10/12/2024") -> 10/12/2024 | L9: 45636 | M9: =IFERROR(__xludf.DUMMYFUNCTION("PROPER(TRIM( REGEXREPLACE( REGEXREPLACE( SUBSTITUTE(SUBSTITUTE(SUBSTITUTE(SUBSTITUTE(SUBSTITUTE(SUBSTITUTE(SUBSTITUTE(SUBSTITUTE(SUBSTITUTE(SUBSTITUTE(SUBSTITUTE( B9,""√©"",""é""),""√°"",""á""),""√±"",""ñ""),""√≥"",""ó""),""√â"",""é"")"&",""√Å"",""á""),""√ç"",""í""),""√Ç"",""Í""),""√Â"",""é""),""√≠"",""í""),""√º"",""ú""), ""[,\\.√]"",""""), ""\\s+"","" "") )) "),"Ciudad De México") -> Ciudad De México | N9: =IFERROR(__xludf.DUMMYFUNCTION("SPLIT( TRIM( SUBSTITUTE( SUBSTITUTE( SUBSTITUTE( SUBSTITUTE( C9, ""√©"", ""é"" ), ""√±"", ""ñ"" ), ""√°"", ""á"" ), ""√≥"", ""ó"" ) ), ""-"" ) "),"Tablet") -> Tablet | O9: =IFERROR(__xludf.DUMMYFUNCTION("""COMPUTED_VALUE"""),"Pro") -> Pro | P9: =IFERROR(__xludf.DUMMYFUNCTION("""COMPUTED_VALUE"""),"8GB") -> 8GB | Q9: =IF(ISBLANK(D9),"0",D9) -> 1001.63 | R9: =IF(ISBLANK(E9),"Sin datos",E9) -> 3 | S9: =IF(ISBLANK(F9),"0",F9) -> 3004.89 | T9: =IFERROR(__xludf.DUMMYFUNCTION("PROPER(TRIM( LET( texto1, REGEXREPLACE(G9, ""(?i)\b(DR\.?|SRA?\.?|\(A\)|MTRO\.?|LIC\.?|ING\.?)\b"", """"), texto2, REGEXREPLACE(texto1, ""√©|√â|√Â"", ""é""), texto3, REGEXREPLACE(texto2, ""√°|√Å"", ""á""), texto4, REGEXREPLACE(texto3, """&"√±"", ""ñ""), texto5, REGEXREPLACE(texto4, ""√≥"", ""ó""), texto6, REGEXREPLACE(texto5, ""√ç|√≠|√Ç"", ""í""), texto7, REGEXREPLACE(texto6, ""√º"", ""ú""), texto8, REGEXREPLACE(texto7, ""[^A-Za-zÁÉÍÓÚÜÑáéíóúüñ\s]"", """"), texto9, REGEX"&"REPLACE(texto8, ""^[A-Za-zÁÉÍÓÚÜÑáéíóúüñ]\s+"", """"), texto10, IF(REGEXMATCH(texto9, ""(?i)^\s*Jos\s*$""), ""José"", texto9), texto11, REGEXREPLACE(texto10, ""(?i)(eé|ée|ee|éé)+"", ""é""), texto12, REGEXREPLACE(texto11, ""(?i)(aá|áa|aa|áá)+"""&", ""á""), texto13, REGEXREPLACE(texto12, ""(?i)(ií|íi|ii|íí)+"", ""í""), texto14, REGEXREPLACE(texto13, ""(?i)(oó|óo|oo|óó)+"", ""ó""), texto15, REGEXREPLACE(texto14, ""(?i)(uú|úu|uu|úú)+"", ""ú""), texto16, REGEXREPLACE(texto15, ""\s{2,}"&""", "" ""), texto16 ) )) "),"Rolando Mares") -> Rolando Mares | U9: =I9 -> 5199a25e-ee56-4e1f-9c71-21f24998e8fc | V9: =CONCATENATE(N9," ",O9," ",P9) -> Tablet Pro 8GB
A10: 15/12/2024 | B10: Cali | C10: Laptop-Ultraliviana-16GB | D10: 181.56 | E10: 4 | F10: 726.24 | G10: Virginia Mondrag√≥n | H10: josefina68@proyectos.com | I10: e58774cc-8183-4c21-b23d-1089685c61dd | K10: =IFERROR(__xludf.DUMMYFUNCTION("IF(ISBLANK(A10), """", IF(ISNUMBER(A10), TEXT(A10,""dd/mm/yyyy""), IF( REGEXMATCH(TRIM(A10),""^\d{1,2}/\d{1,2}/\d{4}$""), TRIM(A10), IFERROR( TEXT(DATEVALUE(SUBSTITUTE(SUBSTITUTE(TRIM(A10),""-"",""/""),""."",""/"")),"&"""dd/mm/yyyy""), TRIM(A10) ) ) ) ) "),"15/12/2024") -> 15/12/2024 | L10: 45641 | M10: =IFERROR(__xludf.DUMMYFUNCTION("PROPER(TRIM( REGEXREPLACE( REGEXREPLACE( SUBSTITUTE(SUBSTITUTE(SUBSTITUTE(SUBSTITUTE(SUBSTITUTE(SUBSTITUTE(SUBSTITUTE(SUBSTITUTE(SUBSTITUTE(SUBSTITUTE(SUBSTITUTE( B10,""√©"",""é""),""√°"",""á""),""√±"",""ñ""),""√≥"",""ó""),""√â"",""é"""&"),""√Å"",""á""),""√ç"",""í""),""√Ç"",""Í""),""√Â"",""é""),""√≠"",""í""),""√º"",""ú""), ""[,\\.√]"",""""), ""\\s+"","" "") )) "),"Cali") -> Cali | N10: =IFERROR(__xludf.DUMMYFUNCTION("SPLIT( TRIM( SUBSTITUTE( SUBSTITUTE( SUBSTITUTE( SUBSTITUTE( C10, ""√©"", ""é"" ), ""√±"", ""ñ"" ), ""√°"", ""á"" ), ""√≥"", ""ó"" ) ), ""-"" ) "),"Laptop") -> Laptop | O10: =IFERROR(__xludf.DUMMYFUNCTION("""COMPUTED_VALUE"""),"Ultraliviana") -> Ultraliviana | P10: =IFERROR(__xludf.DUMMYFUNCTION("""COMPUTED_VALUE"""),"16GB") -> 16GB | Q10: =IF(ISBLANK(D10),"0",D10) -> 181.56 | R10: =IF(ISBLANK(E10),"Sin datos",E10) -> 4 | S10: =IF(ISBLANK(F10),"0",F10) -> 726.24 | T10: =IFERROR(__xludf.DUMMYFUNCTION("PROPER(TRIM( LET( texto1, REGEXREPLACE(G10, ""(?i)\b(DR\.?|SRA?\.?|\(A\)|MTRO\.?|LIC\.?|ING\.?)\b"", """"), texto2, REGEXREPLACE(texto1, ""√©|√â|√Â"", ""é""), texto3, REGEXREPLACE(texto2, ""√°|√Å"", ""á""), texto4, REGEXREPLACE(texto3, "&"""√±"", ""ñ""), texto5, REGEXREPLACE(texto4, ""√≥"", ""ó""), texto6, REGEXREPLACE(texto5, ""√ç|√≠|√Ç"", ""í""), texto7, REGEXREPLACE(texto6, ""√º"", ""ú""), texto8, REGEXREPLACE(texto7, ""[^A-Za-zÁÉÍÓÚÜÑáéíóúüñ\s]"", """"), texto9, REG"&"EXREPLACE(texto8, ""^[A-Za-zÁÉÍÓÚÜÑáéíóúüñ]\s+"", """"), texto10, IF(REGEXMATCH(texto9, ""(?i)^\s*Jos\s*$""), ""José"", texto9), texto11, REGEXREPLACE(texto10, ""(?i)(eé|ée|ee|éé)+"", ""é""), texto12, REGEXREPLACE(texto11, ""(?i)(aá|áa|aa|áá)+"&""", ""á""), texto13, REGEXREPLACE(texto12, ""(?i)(ií|íi|ii|íí)+"", ""í""), texto14, REGEXREPLACE(texto13, ""(?i)(oó|óo|oo|óó)+"", ""ó""), texto15, REGEXREPLACE(texto14, ""(?i)(uú|úu|uu|úú)+"", ""ú""), texto16, REGEXREPLACE(texto15, ""\s{2,"&"}"", "" ""), texto16 ) )) "),"Virginia Mondragón") -> Virginia Mondragón | U10: =I10 -> e58774cc-8183-4c21-b23d-1089685c61dd | V10: =CONCATENATE(N10," ",O10," ",P10) -> Laptop Ultraliviana 16GB
A11: 23/12/2024 | B11: GUADALAJARA | C11: Tablet-Mini-4GB | D11: 964.35 | E11: 5 | F11: 4821.75 | G11: Luis Manuel Aldonza Contreras | H11: castilloteodoro@yahoo.com | I11: 4e85609f-8a23-4d99-a616-2f83279d0dc0 | K11: =IFERROR(__xludf.DUMMYFUNCTION("IF(ISBLANK(A11), """", IF(ISNUMBER(A11), TEXT(A11,""dd/mm/yyyy""), IF( REGEXMATCH(TRIM(A11),""^\d{1,2}/\d{1,2}/\d{4}$""), TRIM(A11), IFERROR( TEXT(DATEVALUE(SUBSTITUTE(SUBSTITUTE(TRIM(A11),""-"",""/""),""."",""/"")),"&"""dd/mm/yyyy""), TRIM(A11) ) ) ) ) "),"23/12/2024") -> 23/12/2024 | L11: 45649 | M11: =IFERROR(__xludf.DUMMYFUNCTION("PROPER(TRIM( REGEXREPLACE( REGEXREPLACE( SUBSTITUTE(SUBSTITUTE(SUBSTITUTE(SUBSTITUTE(SUBSTITUTE(SUBSTITUTE(SUBSTITUTE(SUBSTITUTE(SUBSTITUTE(SUBSTITUTE(SUBSTITUTE( B11,""√©"",""é""),""√°"",""á""),""√±"",""ñ""),""√≥"",""ó""),""√â"",""é"""&"),""√Å"",""á""),""√ç"",""í""),""√Ç"",""Í""),""√Â"",""é""),""√≠"",""í""),""√º"",""ú""), ""[,\\.√]"",""""), ""\\s+"","" "") )) "),"Guadalajara") -> Guadalajara | N11: =IFERROR(__xludf.DUMMYFUNCTION("SPLIT( TRIM( SUBSTITUTE( SUBSTITUTE( SUBSTITUTE( SUBSTITUTE( C11, ""√©"", ""é"" ), ""√±"", ""ñ"" ), ""√°"", ""á"" ), ""√≥"", ""ó"" ) ), ""-"" ) "),"Tablet") -> Tablet | O11: =IFERROR(__xludf.DUMMYFUNCTION("""COMPUTED_VALUE"""),"Mini") -> Mini | P11: =IFERROR(__xludf.DUMMYFUNCTION("""COMPUTED_VALUE"""),"4GB") -> 4GB | Q11: =IF(ISBLANK(D11),"0",D11) -> 964.35 | R11: =IF(ISBLANK(E11),"Sin datos",E11) -> 5 | S11: =IF(ISBLANK(F11),"0",F11) -> 4821.75 | T11: =IFERROR(__xludf.DUMMYFUNCTION("PROPER(TRIM( LET( texto1, REGEXREPLACE(G11, ""(?i)\b(DR\.?|SRA?\.?|\(A\)|MTRO\.?|LIC\.?|ING\.?)\b"", """"), texto2, REGEXREPLACE(texto1, ""√©|√â|√Â"", ""é""), texto3, REGEXREPLACE(texto2, ""√°|√Å"", ""á""), texto4, REGEXREPLACE(texto3, "&"""√±"", ""ñ""), texto5, REGEXREPLACE(texto4, ""√≥"", ""ó""), texto6, REGEXREPLACE(texto5, ""√ç|√≠|√Ç"", ""í""), texto7, REGEXREPLACE(texto6, ""√º"", ""ú""), texto8, REGEXREPLACE(texto7, ""[^A-Za-zÁÉÍÓÚÜÑáéíóúüñ\s]"", """"), texto9, REG"&"EXREPLACE(texto8, ""^[A-Za-zÁÉÍÓÚÜÑáéíóúüñ]\s+"", """"), texto10, IF(REGEXMATCH(texto9, ""(?i)^\s*Jos\s*$""), ""José"", texto9), texto11, REGEXREPLACE(texto10, ""(?i)(eé|ée|ee|éé)+"", ""é""), texto12, REGEXREPLACE(texto11, ""(?i)(aá|áa|aa|áá)+"&""", ""á""), texto13, REGEXREPLACE(texto12, ""(?i)(ií|íi|ii|íí)+"", ""í""), texto14, REGEXREPLACE(texto13, ""(?i)(oó|óo|oo|óó)+"", ""ó""), texto15, REGEXREPLACE(texto14, ""(?i)(uú|úu|uu|úú)+"", ""ú""), texto16, REGEXREPLACE(texto15, ""\s{2,"&"}"", "" ""), texto16 ) )) "),"Luis Manuel Aldonza Contreras") -> Luis Manuel Aldonza Contreras | U11: =I11 -> 4e85609f-8a23-4d99-a616-2f83279d0dc0 | V11: =CONCATENATE(N11," ",O11," ",P11) -> Tablet Mini 4GB
A12: 45574 | B12: Bogotá | C12: Auriculares-Bluetooth-16GB | D12: 120.46 | E12: 1 | F12: 120.46 | G12: Indira Guadalupe Montez Alcaraz | H12: brivera@club.com | I12: a076e80e-95f4-4b8d-8e0e-af032fd3e7e3 | K12: =IFERROR(__xludf.DUMMYFUNCTION("IF(ISBLANK(A12), """", IF(ISNUMBER(A12), TEXT(A12,""dd/mm/yyyy""), IF( REGEXMATCH(TRIM(A12),""^\d{1,2}/\d{1,2}/\d{4}$""), TRIM(A12), IFERROR( TEXT(DATEVALUE(SUBSTITUTE(SUBSTITUTE(TRIM(A12),""-"",""/""),""."",""/"")),"&"""dd/mm/yyyy""), TRIM(A12) ) ) ) ) "),"09/10/2024") -> 09/10/2024 | L12: 45574 | M12: =IFERROR(__xludf.DUMMYFUNCTION("PROPER(TRIM( REGEXREPLACE( REGEXREPLACE( SUBSTITUTE(SUBSTITUTE(SUBSTITUTE(SUBSTITUTE(SUBSTITUTE(SUBSTITUTE(SUBSTITUTE(SUBSTITUTE(SUBSTITUTE(SUBSTITUTE(SUBSTITUTE( B12,""√©"",""é""),""√°"",""á""),""√±"",""ñ""),""√≥"",""ó""),""√â"",""é"""&"),""√Å"",""á""),""√ç"",""í""),""√Ç"",""Í""),""√Â"",""é""),""√≠"",""í""),""√º"",""ú""), ""[,\\.√]"",""""), ""\\s+"","" "") )) "),"Bogotá") -> Bogotá | N12: =IFERROR(__xludf.DUMMYFUNCTION("SPLIT( TRIM( SUBSTITUTE( SUBSTITUTE( SUBSTITUTE( SUBSTITUTE( C12, ""√©"", ""é"" ), ""√±"", ""ñ"" ), ""√°"", ""á"" ), ""√≥"", ""ó"" ) ), ""-"" ) "),"Auriculares") -> Auriculares | O12: =IFERROR(__xludf.DUMMYFUNCTION("""COMPUTED_VALUE"""),"Bluetooth") -> Bluetooth | P12: =IFERROR(__xludf.DUMMYFUNCTION("""COMPUTED_VALUE"""),"16GB") -> 16GB | Q12: =IF(ISBLANK(D12),"0",D12) -> 120.46 | R12: =IF(ISBLANK(E12),"Sin datos",E12) -> 1 | S12: =IF(ISBLANK(F12),"0",F12) -> 120.46 | T12: =IFERROR(__xludf.DUMMYFUNCTION("PROPER(TRIM( LET( texto1, REGEXREPLACE(G12, ""(?i)\b(DR\.?|SRA?\.?|\(A\)|MTRO\.?|LIC\.?|ING\.?)\b"", """"), texto2, REGEXREPLACE(texto1, ""√©|√â|√Â"", ""é""), texto3, REGEXREPLACE(texto2, ""√°|√Å"", ""á""), texto4, REGEXREPLACE(texto3, "&"""√±"", ""ñ""), texto5, REGEXREPLACE(texto4, ""√≥"", ""ó""), texto6, REGEXREPLACE(texto5, ""√ç|√≠|√Ç"", ""í""), texto7, REGEXREPLACE(texto6, ""√º"", ""ú""), texto8, REGEXREPLACE(texto7, ""[^A-Za-zÁÉÍÓÚÜÑáéíóúüñ\s]"", """"), texto9, REG"&"EXREPLACE(texto8, ""^[A-Za-zÁÉÍÓÚÜÑáéíóúüñ]\s+"", """"), texto10, IF(REGEXMATCH(texto9, ""(?i)^\s*Jos\s*$""), ""José"", texto9), texto11, REGEXREPLACE(texto10, ""(?i)(eé|ée|ee|éé)+"", ""é""), texto12, REGEXREPLACE(texto11, ""(?i)(aá|áa|aa|áá)+"&""", ""á""), texto13, REGEXREPLACE(texto12, ""(?i)(ií|íi|ii|íí)+"", ""í""), texto14, REGEXREPLACE(texto13, ""(?i)(oó|óo|oo|óó)+"", ""ó""), texto15, REGEXREPLACE(texto14, ""(?i)(uú|úu|uu|úú)+"", ""ú""), texto16, REGEXREPLACE(texto15, ""\s{2,"&"}"", "" ""), texto16 ) )) "),"Indira Guadalupe Montez Alcaraz") -> Indira Guadalupe Montez Alcaraz | U12: =I12 -> a076e80e-95f4-4b8d-8e0e-af032fd3e7e3 | V12: =CONCATENATE(N12," ",O12," ",P12) -> Auriculares Bluetooth 16GB
A13: 45621 | B13: Medellín | C13: Auriculares-Con cable-16GB | D13: 1061.61 | E13: 1 | F13: 1061.61 | G13: Lic. Luz de la Garza | H13: esparta94@gmail.com | I13: b76b9aa0-31e3-4e6d-905f-d7fc227d629a | K13: =IFERROR(__xludf.DUMMYFUNCTION("IF(ISBLANK(A13), """", IF(ISNUMBER(A13), TEXT(A13,""dd/mm/yyyy""), IF( REGEXMATCH(TRIM(A13),""^\d{1,2}/\d{1,2}/\d{4}$""), TRIM(A13), IFERROR( TEXT(DATEVALUE(SUBSTITUTE(SUBSTITUTE(TRIM(A13),""-"",""/""),""."",""/"")),"&"""dd/mm/yyyy""), TRIM(A13) ) ) ) ) "),"25/11/2024") -> 25/11/2024 | L13: 45621 | M13: =IFERROR(__xludf.DUMMYFUNCTION("PROPER(TRIM( REGEXREPLACE( REGEXREPLACE( SUBSTITUTE(SUBSTITUTE(SUBSTITUTE(SUBSTITUTE(SUBSTITUTE(SUBSTITUTE(SUBSTITUTE(SUBSTITUTE(SUBSTITUTE(SUBSTITUTE(SUBSTITUTE( B13,""√©"",""é""),""√°"",""á""),""√±"",""ñ""),""√≥"",""ó""),""√â"",""é"""&"),""√Å"",""á""),""√ç"",""í""),""√Ç"",""Í""),""√Â"",""é""),""√≠"",""í""),""√º"",""ú""), ""[,\\.√]"",""""), ""\\s+"","" "") )) "),"Medellín") -> Medellín | N13: =IFERROR(__xludf.DUMMYFUNCTION("SPLIT( TRIM( SUBSTITUTE( SUBSTITUTE( SUBSTITUTE( SUBSTITUTE( C13, ""√©"", ""é"" ), ""√±"", ""ñ"" ), ""√°"", ""á"" ), ""√≥"", ""ó"" ) ), ""-"" ) "),"Auriculares") -> Auriculares | O13: =IFERROR(__xludf.DUMMYFUNCTION("""COMPUTED_VALUE"""),"Con cable") -> Con cable | P13: =IFERROR(__xludf.DUMMYFUNCTION("""COMPUTED_VALUE"""),"16GB") -> 16GB | Q13: =IF(ISBLANK(D13),"0",D13) -> 1061.61 | R13: =IF(ISBLANK(E13),"Sin datos",E13) -> 1 | S13: =IF(ISBLANK(F13),"0",F13) -> 1061.61 | T13: =IFERROR(__xludf.DUMMYFUNCTION("PROPER(TRIM( LET( texto1, REGEXREPLACE(G13, ""(?i)\b(DR\.?|SRA?\.?|\(A\)|MTRO\.?|LIC\.?|ING\.?)\b"", """"), texto2, REGEXREPLACE(texto1, ""√©|√â|√Â"", ""é""), texto3, REGEXREPLACE(texto2, ""√°|√Å"", ""á""), texto4, REGEXREPLACE(texto3, "&"""√±"", ""ñ""), texto5, REGEXREPLACE(texto4, ""√≥"", ""ó""), texto6, REGEXREPLACE(texto5, ""√ç|√≠|√Ç"", ""í""), texto7, REGEXREPLACE(texto6, ""√º"", ""ú""), texto8, REGEXREPLACE(texto7, ""[^A-Za-zÁÉÍÓÚÜÑáéíóúüñ\s]"", """"), texto9, REG"&"EXREPLACE(texto8, ""^[A-Za-zÁÉÍÓÚÜÑáéíóúüñ]\s+"", """"), texto10, IF(REGEXMATCH(texto9, ""(?i)^\s*Jos\s*$""), ""José"", texto9), texto11, REGEXREPLACE(texto10, ""(?i)(eé|ée|ee|éé)+"", ""é""), texto12, REGEXREPLACE(texto11, ""(?i)(aá|áa|aa|áá)+"&""", ""á""), texto13, REGEXREPLACE(texto12, ""(?i)(ií|íi|ii|íí)+"", ""í""), texto14, REGEXREPLACE(texto13, ""(?i)(oó|óo|oo|óó)+"", ""ó""), texto15, REGEXREPLACE(texto14, ""(?i)(uú|úu|uu|úú)+"", ""ú""), texto16, REGEXREPLACE(texto15, ""\s{2,"&"}"", "" ""), texto16 ) )) "),"Luz De La Garza") -> Luz De La Garza | U13: =I13 -> b76b9aa0-31e3-4e6d-905f-d7fc227d629a | V13: =CONCATENATE(N13," ",O13," ",P13) -> Auriculares Con cable 16GB
A14: 19/12/2024 | B14: Cali | C14: Tablet-Pro-4GB | D14: 2440.84 | E14: 5 | F14: 12204.2 | G14: Sr(a). Karla Mateo | H14: reynaldo65@esparza.com | I14: fde0973c-ba07-4b7c-b196-f9743e17466a | K14: =IFERROR(__xludf.DUMMYFUNCTION("IF(ISBLANK(A14), """", IF(ISNUMBER(A14), TEXT(A14,""dd/mm/yyyy""), IF( REGEXMATCH(TRIM(A14),""^\d{1,2}/\d{1,2}/\d{4}$""), TRIM(A14), IFERROR( TEXT(DATEVALUE(SUBSTITUTE(SUBSTITUTE(TRIM(A14),""-"",""/""),""."",""/"")),"&"""dd/mm/yyyy""), TRIM(A14) ) ) ) ) "),"19/12/2024") -> 19/12/2024 | L14: 45645 | M14: =IFERROR(__xludf.DUMMYFUNCTION("PROPER(TRIM( REGEXREPLACE( REGEXREPLACE( SUBSTITUTE(SUBSTITUTE(SUBSTITUTE(SUBSTITUTE(SUBSTITUTE(SUBSTITUTE(SUBSTITUTE(SUBSTITUTE(SUBSTITUTE(SUBSTITUTE(SUBSTITUTE( B14,""√©"",""é""),""√°"",""á""),""√±"",""ñ""),""√≥"",""ó""),""√â"",""é"""&"),""√Å"",""á""),""√ç"",""í""),""√Ç"",""Í""),""√Â"",""é""),""√≠"",""í""),""√º"",""ú""), ""[,\\.√]"",""""), ""\\s+"","" "") )) "),"Cali") -> Cali | N14: =IFERROR(__xludf.DUMMYFUNCTION("SPLIT( TRIM( SUBSTITUTE( SUBSTITUTE( SUBSTITUTE( SUBSTITUTE( C14, ""√©"", ""é"" ), ""√±"", ""ñ"" ), ""√°"", ""á"" ), ""√≥"", ""ó"" ) ), ""-"" ) "),"Tablet") -> Tablet | O14: =IFERROR(__xludf.DUMMYFUNCTION("""COMPUTED_VALUE"""),"Pro") -> Pro | P14: =IFERROR(__xludf.DUMMYFUNCTION("""COMPUTED_VALUE"""),"4GB") -> 4GB | Q14: =IF(ISBLANK(D14),"0",D14) -> 2440.84 | R14: =IF(ISBLANK(E14),"Sin datos",E14) -> 5 | S14: =IF(ISBLANK(F14),"0",F14) -> 12204.2 | T14: =IFERROR(__xludf.DUMMYFUNCTION("PROPER(TRIM( LET( texto1, REGEXREPLACE(G14, ""(?i)\b(DR\.?|SRA?\.?|\(A\)|MTRO\.?|LIC\.?|ING\.?)\b"", """"), texto2, REGEXREPLACE(texto1, ""√©|√â|√Â"", ""é""), texto3, REGEXREPLACE(texto2, ""√°|√Å"", ""á""), texto4, REGEXREPLACE(texto3, "&"""√±"", ""ñ""), texto5, REGEXREPLACE(texto4, ""√≥"", ""ó""), texto6, REGEXREPLACE(texto5, ""√ç|√≠|√Ç"", ""í""), texto7, REGEXREPLACE(texto6, ""√º"", ""ú""), texto8, REGEXREPLACE(texto7, ""[^A-Za-zÁÉÍÓÚÜÑáéíóúüñ\s]"", """"), texto9, REG"&"EXREPLACE(texto8, ""^[A-Za-zÁÉÍÓÚÜÑáéíóúüñ]\s+"", """"), texto10, IF(REGEXMATCH(texto9, ""(?i)^\s*Jos\s*$""), ""José"", texto9), texto11, REGEXREPLACE(texto10, ""(?i)(eé|ée|ee|éé)+"", ""é""), texto12, REGEXREPLACE(texto11, ""(?i)(aá|áa|aa|áá)+"&""", ""á""), texto13, REGEXREPLACE(texto12, ""(?i)(ií|íi|ii|íí)+"", ""í""), texto14, REGEXREPLACE(texto13, ""(?i)(oó|óo|oo|óó)+"", ""ó""), texto15, REGEXREPLACE(texto14, ""(?i)(uú|úu|uu|úú)+"", ""ú""), texto16, REGEXREPLACE(texto15, ""\s{2,"&"}"", "" ""), texto16 ) )) "),"Karla Mateo") -> Karla Mateo | U14: =I14 -> fde0973c-ba07-4b7c-b196-f9743e17466a | V14: =CONCATENATE(N14," ",O14," ",P14) -> Tablet Pro 4GB
A15: 45586 | B15: Monterrey | C15: Teléfono-Gama baja-16GB | D15: 121.68 | E15: 2 | F15: 243.36 | G15: Abril Julio T√≥rrez Segovia | H15: xsaenz@hotmail.com | I15: 0281b754-3298-47cb-85b3-b7e7a8c57bab | K15: =IFERROR(__xludf.DUMMYFUNCTION("IF(ISBLANK(A15), """", IF(ISNUMBER(A15), TEXT(A15,""dd/mm/yyyy""), IF( REGEXMATCH(TRIM(A15),""^\d{1,2}/\d{1,2}/\d{4}$""), TRIM(A15), IFERROR( TEXT(DATEVALUE(SUBSTITUTE(SUBSTITUTE(TRIM(A15),""-"",""/""),""."",""/"")),"&"""dd/mm/yyyy""), TRIM(A15) ) ) ) ) "),"21/10/2024") -> 21/10/2024 | L15: 45586 | M15: =IFERROR(__xludf.DUMMYFUNCTION("PROPER(TRIM( REGEXREPLACE( REGEXREPLACE( SUBSTITUTE(SUBSTITUTE(SUBSTITUTE(SUBSTITUTE(SUBSTITUTE(SUBSTITUTE(SUBSTITUTE(SUBSTITUTE(SUBSTITUTE(SUBSTITUTE(SUBSTITUTE( B15,""√©"",""é""),""√°"",""á""),""√±"",""ñ""),""√≥"",""ó""),""√â"",""é"""&"),""√Å"",""á""),""√ç"",""í""),""√Ç"",""Í""),""√Â"",""é""),""√≠"",""í""),""√º"",""ú""), ""[,\\.√]"",""""), ""\\s+"","" "") )) "),"Monterrey") -> Monterrey | N15: =IFERROR(__xludf.DUMMYFUNCTION("SPLIT( TRIM( SUBSTITUTE( SUBSTITUTE( SUBSTITUTE( SUBSTITUTE( C15, ""√©"", ""é"" ), ""√±"", ""ñ"" ), ""√°"", ""á"" ), ""√≥"", ""ó"" ) ), ""-"" ) "),"Teléfono") -> Teléfono | O15: =IFERROR(__xludf.DUMMYFUNCTION("""COMPUTED_VALUE"""),"Gama baja") -> Gama baja | P15: =IFERROR(__xludf.DUMMYFUNCTION("""COMPUTED_VALUE"""),"16GB") -> 16GB | Q15: =IF(ISBLANK(D15),"0",D15) -> 121.68 | R15: =IF(ISBLANK(E15),"Sin datos",E15) -> 2 | S15: =IF(ISBLANK(F15),"0",F15) -> 243.36 | T15: =IFERROR(__xludf.DUMMYFUNCTION("PROPER(TRIM( LET( texto1, REGEXREPLACE(G15, ""(?i)\b(DR\.?|SRA?\.?|\(A\)|MTRO\.?|LIC\.?|ING\.?)\b"", """"), texto2, REGEXREPLACE(texto1, ""√©|√â|√Â"", ""é""), texto3, REGEXREPLACE(texto2, ""√°|√Å"", ""á""), texto4, REGEXREPLACE(texto3, "&"""√±"", ""ñ""), texto5, REGEXREPLACE(texto4, ""√≥"", ""ó""), texto6, REGEXREPLACE(texto5, ""√ç|√≠|√Ç"", ""í""), texto7, REGEXREPLACE(texto6, ""√º"", ""ú""), texto8, REGEXREPLACE(texto7, ""[^A-Za-zÁÉÍÓÚÜÑáéíóúüñ\s]"", """"), texto9, REG"&"EXREPLACE(texto8, ""^[A-Za-zÁÉÍÓÚÜÑáéíóúüñ]\s+"", """"), texto10, IF(REGEXMATCH(texto9, ""(?i)^\s*Jos\s*$""), ""José"", texto9), texto11, REGEXREPLACE(texto10, ""(?i)(eé|ée|ee|éé)+"", ""é""), texto12, REGEXREPLACE(texto11, ""(?i)(aá|áa|aa|áá)+"&""", ""á""), texto13, REGEXREPLACE(texto12, ""(?i)(ií|íi|ii|íí)+"", ""í""), texto14, REGEXREPLACE(texto13, ""(?i)(oó|óo|oo|óó)+"", ""ó""), texto15, REGEXREPLACE(texto14, ""(?i)(uú|úu|uu|úú)+"", ""ú""), texto16, REGEXREPLACE(texto15, ""\s{2,"&"}"", "" ""), texto16 ) )) "),"Abril Julio Tórrez Segovia") -> Abril Julio Tórrez Segovia | U15: =I15 -> 0281b754-3298-47cb-85b3-b7e7a8c57bab | V15: =CONCATENATE(N15," ",O15," ",P15) -> Teléfono Gama baja 16GB
A16: 45626 | B16: Guadalajara | C16: Tablet-Pro-32GB | D16: 1109.64 | E16: 3 | G16: Ing. Esteban Curiel | H16: juliavergara@barraza.info | I16: 6d6dc8da-1c46-48a9-9864-d6731b144bc7 | K16: =IFERROR(__xludf.DUMMYFUNCTION("IF(ISBLANK(A16), """", IF(ISNUMBER(A16), TEXT(A16,""dd/mm/yyyy""), IF( REGEXMATCH(TRIM(A16),""^\d{1,2}/\d{1,2}/\d{4}$""), TRIM(A16), IFERROR( TEXT(DATEVALUE(SUBSTITUTE(SUBSTITUTE(TRIM(A16),""-"",""/""),""."",""/"")),"&"""dd/mm/yyyy""), TRIM(A16) ) ) ) ) "),"30/11/2024") -> 30/11/2024 | L16: 45626 | M16: =IFERROR(__xludf.DUMMYFUNCTION("PROPER(TRIM( REGEXREPLACE( REGEXREPLACE( SUBSTITUTE(SUBSTITUTE(SUBSTITUTE(SUBSTITUTE(SUBSTITUTE(SUBSTITUTE(SUBSTITUTE(SUBSTITUTE(SUBSTITUTE(SUBSTITUTE(SUBSTITUTE( B16,""√©"",""é""),""√°"",""á""),""√±"",""ñ""),""√≥"",""ó""),""√â"",""é"""&"),""√Å"",""á""),""√ç"",""í""),""√Ç"",""Í""),""√Â"",""é""),""√≠"",""í""),""√º"",""ú""), ""[,\\.√]"",""""), ""\\s+"","" "") )) "),"Guadalajara") -> Guadalajara | N16: =IFERROR(__xludf.DUMMYFUNCTION("SPLIT( TRIM( SUBSTITUTE( SUBSTITUTE( SUBSTITUTE( SUBSTITUTE( C16, ""√©"", ""é"" ), ""√±"", ""ñ"" ), ""√°"", ""á"" ), ""√≥"", ""ó"" ) ), ""-"" ) "),"Tablet") -> Tablet | O16: =IFERROR(__xludf.DUMMYFUNCTION("""COMPUTED_VALUE"""),"Pro") -> Pro | P16: =IFERROR(__xludf.DUMMYFUNCTION("""COMPUTED_VALUE"""),"32GB") -> 32GB | Q16: =IF(ISBLANK(D16),"0",D16) -> 1109.64 | R16: =IF(ISBLANK(E16),"Sin datos",E16) -> 3 | S16: =IF(ISBLANK(F16),"0",F16) -> 0 | T16: =IFERROR(__xludf.DUMMYFUNCTION("PROPER(TRIM( LET( texto1, REGEXREPLACE(G16, ""(?i)\b(DR\.?|SRA?\.?|\(A\)|MTRO\.?|LIC\.?|ING\.?)\b"", """"), texto2, REGEXREPLACE(texto1, ""√©|√â|√Â"", ""é""), texto3, REGEXREPLACE(texto2, ""√°|√Å"", ""á""), texto4, REGEXREPLACE(texto3, "&"""√±"", ""ñ""), texto5, REGEXREPLACE(texto4, ""√≥"", ""ó""), texto6, REGEXREPLACE(texto5, ""√ç|√≠|√Ç"", ""í""), texto7, REGEXREPLACE(texto6, ""√º"", ""ú""), texto8, REGEXREPLACE(texto7, ""[^A-Za-zÁÉÍÓÚÜÑáéíóúüñ\s]"", """"), texto9, REG"&"EXREPLACE(texto8, ""^[A-Za-zÁÉÍÓÚÜÑáéíóúüñ]\s+"", """"), texto10, IF(REGEXMATCH(texto9, ""(?i)^\s*Jos\s*$""), ""José"", texto9), texto11, REGEXREPLACE(texto10, ""(?i)(eé|ée|ee|éé)+"", ""é""), texto12, REGEXREPLACE(texto11, ""(?i)(aá|áa|aa|áá)+"&""", ""á""), texto13, REGEXREPLACE(texto12, ""(?i)(ií|íi|ii|íí)+"", ""í""), texto14, REGEXREPLACE(texto13, ""(?i)(oó|óo|oo|óó)+"", ""ó""), texto15, REGEXREPLACE(texto14, ""(?i)(uú|úu|uu|úú)+"", ""ú""), texto16, REGEXREPLACE(texto15, ""\s{2,"&"}"", "" ""), texto16 ) )) "),"Esteban Curiel") -> Esteban Curiel | U16: =I16 -> 6d6dc8da-1c46-48a9-9864-d6731b144bc7 | V16: =CONCATENATE(N16," ",O16," ",P16) -> Tablet Pro 32GB
A17: 45631 | B17: Guadalajara | C17: Tablet-Mini-32GB | D17: 2246.48 | E17: 1 | F17: 2246.48 | G17: Hilda M√≥nica Acu√±a Zedillo | H17: lhidalgo@yahoo.com | I17: 6d865eac-7ee1-4c9f-bf09-98a0163a585b | K17: =IFERROR(__xludf.DUMMYFUNCTION("IF(ISBLANK(A17), """", IF(ISNUMBER(A17), TEXT(A17,""dd/mm/yyyy""), IF( REGEXMATCH(TRIM(A17),""^\d{1,2}/\d{1,2}/\d{4}$""), TRIM(A17), IFERROR( TEXT(DATEVALUE(SUBSTITUTE(SUBSTITUTE(TRIM(A17),""-"",""/""),""."",""/"")),"&"""dd/mm/yyyy""), TRIM(A17) ) ) ) ) "),"05/12/2024") -> 05/12/2024 | L17: 45631 | M17: =IFERROR(__xludf.DUMMYFUNCTION("PROPER(TRIM( REGEXREPLACE( REGEXREPLACE( SUBSTITUTE(SUBSTITUTE(SUBSTITUTE(SUBSTITUTE(SUBSTITUTE(SUBSTITUTE(SUBSTITUTE(SUBSTITUTE(SUBSTITUTE(SUBSTITUTE(SUBSTITUTE( B17,""√©"",""é""),""√°"",""á""),""√±"",""ñ""),""√≥"",""ó""),""√â"",""é"""&"),""√Å"",""á""),""√ç"",""í""),""√Ç"",""Í""),""√Â"",""é""),""√≠"",""í""),""√º"",""ú""), ""[,\\.√]"",""""), ""\\s+"","" "") )) "),"Guadalajara") -> Guadalajara | N17: =IFERROR(__xludf.DUMMYFUNCTION("SPLIT( TRIM( SUBSTITUTE( SUBSTITUTE( SUBSTITUTE( SUBSTITUTE( C17, ""√©"", ""é"" ), ""√±"", ""ñ"" ), ""√°"", ""á"" ), ""√≥"", ""ó"" ) ), ""-"" ) "),"Tablet") -> Tablet | O17: =IFERROR(__xludf.DUMMYFUNCTION("""COMPUTED_VALUE"""),"Mini") -> Mini | P17: =IFERROR(__xludf.DUMMYFUNCTION("""COMPUTED_VALUE"""),"32GB") -> 32GB | Q17: =IF(ISBLANK(D17),"0",D17) -> 2246.48 | R17: =IF(ISBLANK(E17),"Sin datos",E17) -> 1 | S17: =IF(ISBLANK(F17),"0",F17) -> 2246.48 | T17: =IFERROR(__xludf.DUMMYFUNCTION("PROPER(TRIM( LET( texto1, REGEXREPLACE(G17, ""(?i)\b(DR\.?|SRA?\.?|\(A\)|MTRO\.?|LIC\.?|ING\.?)\b"", """"), texto2, REGEXREPLACE(texto1, ""√©|√â|√Â"", ""é""), texto3, REGEXREPLACE(texto2, ""√°|√Å"", ""á""), texto4, REGEXREPLACE(texto3, "&"""√±"", ""ñ""), texto5, REGEXREPLACE(texto4, ""√≥"", ""ó""), texto6, REGEXREPLACE(texto5, ""√ç|√≠|√Ç"", ""í""), texto7, REGEXREPLACE(texto6, ""√º"", ""ú""), texto8, REGEXREPLACE(texto7, ""[^A-Za-zÁÉÍÓÚÜÑáéíóúüñ\s]"", """"), texto9, REG"&"EXREPLACE(texto8, ""^[A-Za-zÁÉÍÓÚÜÑáéíóúüñ]\s+"", """"), texto10, IF(REGEXMATCH(texto9, ""(?i)^\s*Jos\s*$""), ""José"", texto9), texto11, REGEXREPLACE(texto10, ""(?i)(eé|ée|ee|éé)+"", ""é""), texto12, REGEXREPLACE(texto11, ""(?i)(aá|áa|aa|áá)+"&""", ""á""), texto13, REGEXREPLACE(texto12, ""(?i)(ií|íi|ii|íí)+"", ""í""), texto14, REGEXREPLACE(texto13, ""(?i)(oó|óo|oo|óó)+"", ""ó""), texto15, REGEXREPLACE(texto14, ""(?i)(uú|úu|uu|úú)+"", ""ú""), texto16, REGEXREPLACE(texto15, ""\s{2,"&"}"", "" ""), texto16 ) )) "),"Hilda Mónica Acuña Zedillo") -> Hilda Mónica Acuña Zedillo | U17: =I17 -> 6d865eac-7ee1-4c9f-bf09-98a0163a585b | V17: =CONCATENATE(N17," ",O17," ",P17) -> Tablet Mini 32GB
A18: 22/10/2024 | B18: Bogotá | C18: Auriculares-Cancelación de ruido-4GB | D18: 129.07 | E18: 4 | F18: 516.28 | G18: Iv√°n Sanches Vallejo | H18: reinaenriquez@sarabia-badillo.com | I18: 166ba421-1a83-493d-b4f5-5832605721e4 | K18: =IFERROR(__xludf.DUMMYFUNCTION("IF(ISBLANK(A18), """", IF(ISNUMBER(A18), TEXT(A18,""dd/mm/yyyy""), IF( REGEXMATCH(TRIM(A18),""^\d{1,2}/\d{1,2}/\d{4}$""), TRIM(A18), IFERROR( TEXT(DATEVALUE(SUBSTITUTE(SUBSTITUTE(TRIM(A18),""-"",""/""),""."",""/"")),"&"""dd/mm/yyyy""), TRIM(A18) ) ) ) ) "),"22/10/2024") -> 22/10/2024 | L18: 45587 | M18: =IFERROR(__xludf.DUMMYFUNCTION("PROPER(TRIM( REGEXREPLACE( REGEXREPLACE( SUBSTITUTE(SUBSTITUTE(SUBSTITUTE(SUBSTITUTE(SUBSTITUTE(SUBSTITUTE(SUBSTITUTE(SUBSTITUTE(SUBSTITUTE(SUBSTITUTE(SUBSTITUTE( B18,""√©"",""é""),""√°"",""á""),""√±"",""ñ""),""√≥"",""ó""),""√â"",""é"""&"),""√Å"",""á""),""√ç"",""í""),""√Ç"",""Í""),""√Â"",""é""),""√≠"",""í""),""√º"",""ú""), ""[,\\.√]"",""""), ""\\s+"","" "") )) "),"Bogotá") -> Bogotá | N18: =IFERROR(__xludf.DUMMYFUNCTION("SPLIT( TRIM( SUBSTITUTE( SUBSTITUTE( SUBSTITUTE( SUBSTITUTE( C18, ""√©"", ""é"" ), ""√±"", ""ñ"" ), ""√°"", ""á"" ), ""√≥"", ""ó"" ) ), ""-"" ) "),"Auriculares") -> Auriculares | O18: =IFERROR(__xludf.DUMMYFUNCTION("""COMPUTED_VALUE"""),"Cancelación de ruido") -> Cancelación de ruido | P18: =IFERROR(__xludf.DUMMYFUNCTION("""COMPUTED_VALUE"""),"4GB") -> 4GB | Q18: =IF(ISBLANK(D18),"0",D18) -> 129.07 | R18: =IF(ISBLANK(E18),"Sin datos",E18) -> 4 | S18: =IF(ISBLANK(F18),"0",F18) -> 516.28 | T18: =IFERROR(__xludf.DUMMYFUNCTION("PROPER(TRIM( LET( texto1, REGEXREPLACE(G18, ""(?i)\b(DR\.?|SRA?\.?|\(A\)|MTRO\.?|LIC\.?|ING\.?)\b"", """"), texto2, REGEXREPLACE(texto1, ""√©|√â|√Â"", ""é""), texto3, REGEXREPLACE(texto2, ""√°|√Å"", ""á""), texto4, REGEXREPLACE(texto3, "&"""√±"", ""ñ""), texto5, REGEXREPLACE(texto4, ""√≥"", ""ó""), texto6, REGEXREPLACE(texto5, ""√ç|√≠|√Ç"", ""í""), texto7, REGEXREPLACE(texto6, ""√º"", ""ú""), texto8, REGEXREPLACE(texto7, ""[^A-Za-zÁÉÍÓÚÜÑáéíóúüñ\s]"", """"), texto9, REG"&"EXREPLACE(texto8, ""^[A-Za-zÁÉÍÓÚÜÑáéíóúüñ]\s+"", """"), texto10, IF(REGEXMATCH(texto9, ""(?i)^\s*Jos\s*$""), ""José"", texto9), texto11, REGEXREPLACE(texto10, ""(?i)(eé|ée|ee|éé)+"", ""é""), texto12, REGEXREPLACE(texto11, ""(?i)(aá|áa|aa|áá)+"&""", ""á""), texto13, REGEXREPLACE(texto12, ""(?i)(ií|íi|ii|íí)+"", ""í""), texto14, REGEXREPLACE(texto13, ""(?i)(oó|óo|oo|óó)+"", ""ó""), texto15, REGEXREPLACE(texto14, ""(?i)(uú|úu|uu|úú)+"", ""ú""), texto16, REGEXREPLACE(texto15, ""\s{2,"&"}"", "" ""), texto16 ) )) "),"Iván Sanches Vallejo") -> Iván Sanches Vallejo | U18: =I18 -> 166ba421-1a83-493d-b4f5-5832605721e4 | V18: =CONCATENATE(N18," ",O18," ",P18) -> Auriculares Cancelación de ruido 4GB
A19: 45654 | B19: Monterrey | C19: Auriculares-Bluetooth-16GB | D19: 1724.31 | E19: 2 | F19: 3448.62 | G19: Alejandra Rold√°n | H19: almafajardo@proyectos.com | I19: 530801f5-4c88-4d00-b297-5944ebece83d | K19: =IFERROR(__xludf.DUMMYFUNCTION("IF(ISBLANK(A19), """", IF(ISNUMBER(A19), TEXT(A19,""dd/mm/yyyy""), IF( REGEXMATCH(TRIM(A19),""^\d{1,2}/\d{1,2}/\d{4}$""), TRIM(A19), IFERROR( TEXT(DATEVALUE(SUBSTITUTE(SUBSTITUTE(TRIM(A19),""-"",""/""),""."",""/"")),"&"""dd/mm/yyyy""), TRIM(A19) ) ) ) ) "),"28/12/2024") -> 28/12/2024 | L19: 45654 | M19: =IFERROR(__xludf.DUMMYFUNCTION("PROPER(TRIM( REGEXREPLACE( REGEXREPLACE( SUBSTITUTE(SUBSTITUTE(SUBSTITUTE(SUBSTITUTE(SUBSTITUTE(SUBSTITUTE(SUBSTITUTE(SUBSTITUTE(SUBSTITUTE(SUBSTITUTE(SUBSTITUTE( B19,""√©"",""é""),""√°"",""á""),""√±"",""ñ""),""√≥"",""ó""),""√â"",""é"""&"),""√Å"",""á""),""√ç"",""í""),""√Ç"",""Í""),""√Â"",""é""),""√≠"",""í""),""√º"",""ú""), ""[,\\.√]"",""""), ""\\s+"","" "") )) "),"Monterrey") -> Monterrey | N19: =IFERROR(__xludf.DUMMYFUNCTION("SPLIT( TRIM( SUBSTITUTE( SUBSTITUTE( SUBSTITUTE( SUBSTITUTE( C19, ""√©"", ""é"" ), ""√±"", ""ñ"" ), ""√°"", ""á"" ), ""√≥"", ""ó"" ) ), ""-"" ) "),"Auriculares") -> Auriculares | O19: =IFERROR(__xludf.DUMMYFUNCTION("""COMPUTED_VALUE"""),"Bluetooth") -> Bluetooth | P19: =IFERROR(__xludf.DUMMYFUNCTION("""COMPUTED_VALUE"""),"16GB") -> 16GB | Q19: =IF(ISBLANK(D19),"0",D19) -> 1724.31 | R19: =IF(ISBLANK(E19),"Sin datos",E19) -> 2 | S19: =IF(ISBLANK(F19),"0",F19) -> 3448.62 | T19: =IFERROR(__xludf.DUMMYFUNCTION("PROPER(TRIM( LET( texto1, REGEXREPLACE(G19, ""(?i)\b(DR\.?|SRA?\.?|\(A\)|MTRO\.?|LIC\.?|ING\.?)\b"", """"), texto2, REGEXREPLACE(texto1, ""√©|√â|√Â"", ""é""), texto3, REGEXREPLACE(texto2, ""√°|√Å"", ""á""), texto4, REGEXREPLACE(texto3, "&"""√±"", ""ñ""), texto5, REGEXREPLACE(texto4, ""√≥"", ""ó""), texto6, REGEXREPLACE(texto5, ""√ç|√≠|√Ç"", ""í""), texto7, REGEXREPLACE(texto6, ""√º"", ""ú""), texto8, REGEXREPLACE(texto7, ""[^A-Za-zÁÉÍÓÚÜÑáéíóúüñ\s]"", """"), texto9, REG"&"EXREPLACE(texto8, ""^[A-Za-zÁÉÍÓÚÜÑáéíóúüñ]\s+"", """"), texto10, IF(REGEXMATCH(texto9, ""(?i)^\s*Jos\s*$""), ""José"", texto9), texto11, REGEXREPLACE(texto10, ""(?i)(eé|ée|ee|éé)+"", ""é""), texto12, REGEXREPLACE(texto11, ""(?i)(aá|áa|aa|áá)+"&""", ""á""), texto13, REGEXREPLACE(texto12, ""(?i)(ií|íi|ii|íí)+"", ""í""), texto14, REGEXREPLACE(texto13, ""(?i)(oó|óo|oo|óó)+"", ""ó""), texto15, REGEXREPLACE(texto14, ""(?i)(uú|úu|uu|úú)+"", ""ú""), texto16, REGEXREPLACE(texto15, ""\s{2,"&"}"", "" ""), texto16 ) )) "),"Alejandra Roldán") -> Alejandra Roldán | U19: =I19 -> 530801f5-4c88-4d00-b297-5944ebece83d | V19: =CONCATENATE(N19," ",O19," ",P19) -> Auriculares Bluetooth 16GB
A20: 45577 | B20: Bogotá | C20: Teléfono-Gama alta-16GB | D20: 1445.1 | E20: 4 | F20: 5780.4 | G20: Lorenzo Wendolin M√©ndez Gollum | H20: ffuentes@ochoa-molina.com | I20: 116022d7-56fc-4596-aeba-30c58ab21dbf | K20: =IFERROR(__xludf.DUMMYFUNCTION("IF(ISBLANK(A20), """", IF(ISNUMBER(A20), TEXT(A20,""dd/mm/yyyy""), IF( REGEXMATCH(TRIM(A20),""^\d{1,2}/\d{1,2}/\d{4}$""), TRIM(A20), IFERROR( TEXT(DATEVALUE(SUBSTITUTE(SUBSTITUTE(TRIM(A20),""-"",""/""),""."",""/"")),"&"""dd/mm/yyyy""), TRIM(A20) ) ) ) ) "),"12/10/2024") -> 12/10/2024 | L20: 45577 | M20: =IFERROR(__xludf.DUMMYFUNCTION("PROPER(TRIM( REGEXREPLACE( REGEXREPLACE( SUBSTITUTE(SUBSTITUTE(SUBSTITUTE(SUBSTITUTE(SUBSTITUTE(SUBSTITUTE(SUBSTITUTE(SUBSTITUTE(SUBSTITUTE(SUBSTITUTE(SUBSTITUTE( B20,""√©"",""é""),""√°"",""á""),""√±"",""ñ""),""√≥"",""ó""),""√â"",""é"""&"),""√Å"",""á""),""√ç"",""í""),""√Ç"",""Í""),""√Â"",""é""),""√≠"",""í""),""√º"",""ú""), ""[,\\.√]"",""""), ""\\s+"","" "") )) "),"Bogotá") -> Bogotá | N20: =IFERROR(__xludf.DUMMYFUNCTION("SPLIT( TRIM( SUBSTITUTE( SUBSTITUTE( SUBSTITUTE( SUBSTITUTE( C20, ""√©"", ""é"" ), ""√±"", ""ñ"" ), ""√°"", ""á"" ), ""√≥"", ""ó"" ) ), ""-"" ) "),"Teléfono") -> Teléfono | O20: =IFERROR(__xludf.DUMMYFUNCTION("""COMPUTED_VALUE"""),"Gama alta") -> Gama alta | P20: =IFERROR(__xludf.DUMMYFUNCTION("""COMPUTED_VALUE"""),"16GB") -> 16GB | Q20: =IF(ISBLANK(D20),"0",D20) -> 1445.1 | R20: =IF(ISBLANK(E20),"Sin datos",E20) -> 4 | S20: =IF(ISBLANK(F20),"0",F20) -> 5780.4 | T20: =IFERROR(__xludf.DUMMYFUNCTION("PROPER(TRIM( LET( texto1, REGEXREPLACE(G20, ""(?i)\b(DR\.?|SRA?\.?|\(A\)|MTRO\.?|LIC\.?|ING\.?)\b"", """"), texto2, REGEXREPLACE(texto1, ""√©|√â|√Â"", ""é""), texto3, REGEXREPLACE(texto2, ""√°|√Å"", ""á""), texto4, REGEXREPLACE(texto3, "&"""√±"", ""ñ""), texto5, REGEXREPLACE(texto4, ""√≥"", ""ó""), texto6, REGEXREPLACE(texto5, ""√ç|√≠|√Ç"", ""í""), texto7, REGEXREPLACE(texto6, ""√º"", ""ú""), texto8, REGEXREPLACE(texto7, ""[^A-Za-zÁÉÍÓÚÜÑáéíóúüñ\s]"", """"), texto9, REG"&"EXREPLACE(texto8, ""^[A-Za-zÁÉÍÓÚÜÑáéíóúüñ]\s+"", """"), texto10, IF(REGEXMATCH(texto9, ""(?i)^\s*Jos\s*$""), ""José"", texto9), texto11, REGEXREPLACE(texto10, ""(?i)(eé|ée|ee|éé)+"", ""é""), texto12, REGEXREPLACE(texto11, ""(?i)(aá|áa|aa|áá)+"&""", ""á""), texto13, REGEXREPLACE(texto12, ""(?i)(ií|íi|ii|íí)+"", ""í""), texto14, REGEXREPLACE(texto13, ""(?i)(oó|óo|oo|óó)+"", ""ó""), texto15, REGEXREPLACE(texto14, ""(?i)(uú|úu|uu|úú)+"", ""ú""), texto16, REGEXREPLACE(texto15, ""\s{2,"&"}"", "" ""), texto16 ) )) "),"Lorenzo Wendolin Méndez Gollum") -> Lorenzo Wendolin Méndez Gollum | U20: =I20 -> 116022d7-56fc-4596-aeba-30c58ab21dbf | V20: =CONCATENATE(N20," ",O20," ",P20) -> Teléfono Gama alta 16GB
